Workbook
Name _Hlk114062637: Checklist!$C$69

Sheet prep_table
A1: R0 | B1: library_id | C1: library_name | D1: requestor | E1: pool | F1: plate_well | G1: qPCR date | H1: PCR cycles | I1: index_well | J1: kit_i7 | K1: name_i7 | L1: sequence_i7 | M1: kit_i5 | N1: name_i5 | O1: sequence_i5 | P1: lib_conc_ng_ul | Q1: pooling
A2: 1
A3: 2
A4: 3
A5: 4
A6: 5
A7: 6
A8: 7
A9: 8
A10: 9
A11: 10
A12: 11
A13: 12
... A97: 96

Sheet Checklist
C1: ATAC checklist
A2: Library prep number:
A3: SOP Version:
A4: NEBNext HF 2x ready MM LOT: | L4: Indexplate: | N4: SetA, B, C or D
A5: Library person: | K5: Signature:
A6: Library date:
A7: Comments:
A8: Number of samples: | F8: =MOD(E8,12)=0 -> TRUE | G8: =ROUNDDOWN((E8/12),0) -> 0 | H8: =E8-G8*12 -> 0
B9: Perform qPCR
B10: =IF($F$8=TRUE,CONCATENATE("Pipet ",FIXED($E$8*SUM(F13:F16)/12*1.1)," µL of MM into each well of row 2 of MM plate"),CONCATENATE("Pipet ",(($G$8+1)*SUM((F13:F16))*1.1)," µL of MM into first ",$H$8," wells and ",(($G$8)*(SUM(F13:F16))*1.1)," µL into the other wells of MM plate row 2")) -> Pipet 0.00 µL of MM into each well of row 2 of MM plate
F11: Volume per reaction | G11: =CONCATENATE(" Volume for ",$E$8, " samples") -> Volume for samples
B12: Mix: | C12: gDNA Sample | F12: 1 | G12: - | I12: µL
C13: Index Primer ( i7+i5) | F13: 1 | G13: =F13*1.1*$E$8 -> 0 | I13: µL
C14: H2O | F14: 2.9 | G14: =F14*1.1*$E$8 -> 0 | I14: µL
C15: NEBNext HF 2x ready MM | F15: 5 | G15: =F15*1.1*$E$8 -> 0 | I15: µL
C16: 100x SYBR green | F16: 0.1 | G16: =F16*1.1*$E$8 -> 0 | I16: µL
C17: Total Volume | F17: =SUM(F12:F16) -> 10 | G17: - | I17: µL | J17: mix, spin
B18: Run the following programm: | G18: 72˚/5 min
G19: 98˚/30s
G20: 98˚/10s | I20: 25 cycles
G21: 69˚/30s
G22: 72˚/1min
B23: Library preparation
B24: =IF($F$8=TRUE,CONCATENATE("Pipet ",FIXED($E$8*SUM(F27:F29)/12*1.1)," µL of MM into each well of row 2 of MM plate"),CONCATENATE("Pipet ",(($G$8+1)*SUM((F27:F29))*1.1)," µL of MM into first ",$H$8," wells and ",(($G$8)*(SUM(F27:F29))*1.1)," µL into the other wells of MM plate row 2")) -> Pipet 0.00 µL of MM into each well of row 2 of MM plate
F25: Volume per reaction | G25: =CONCATENATE(" Volume for ",$E$8, " samples") -> Volume for samples
B26: Mix: | C26: gDNA Sample | F26: 1 | G26: - | I26: µL
C27: Index Primer ( i7+i5) | F27: 1 | G27: =F27*1.1*$E$8 -> 0 | I27: µL
C28: H2O | F28: 2.9 | G28: =F28*1.1*$E$8 -> 0 | I28: µL
C29: NEBNext HF 2x ready MM | F29: 5 | G29: =F29*1.1*$E$8 -> 0 | I29: µL
C30: Total Volume | F30: =SUM(F26:F29) -> 9.9 | G30: - | I30: µL | J30: mix, spin
B31: Indicate which Twist UDI Primers you used: | J31: Plate:
C32: 1 | D32: 2 | E32: 3 | F32: 4 | G32: 5 | H32: 6 | I32: 7 | J32: 8 | K32: 9 | L32: 10 | M32: 11 | N32: 12
B33: A
B34: B
B35: C
B36: D
B37: E
B38: F
B39: G
B40: H
...

Sheet Indexes
A1: Number | B1: plate | C1: well | D1: Barcode Sequence i7 | E1: Library Adapter i7 | F1: Barcode Sequence i5 | G1: Library Adapter i5
A2: 1 | B2: A | C2: A01 | D2: TAAGGCGA | E2: N701 | F2: TAGATCGC | G2: S501
A3: 2 | B3: A | C3: A02 | D3: CGTACTAG | E3: N702 | F3: TAGATCGC | G3: S501
A4: 3 | B4: A | C4: A03 | D4: AGGCAGAA | E4: N703 | F4: TAGATCGC | G4: S501
A5: 4 | B5: A | C5: A04 | D5: TCCTGAGC | E5: N704 | F5: TAGATCGC | G5: S501
A6: 5 | B6: A | C6: A05 | D6: GGACTCCT | E6: N705 | F6: TAGATCGC | G6: S501
A7: 6 | B7: A | C7: A06 | D7: TAGGCATG | E7: N706 | F7: TAGATCGC | G7: S501
A8: 7 | B8: A | C8: A07 | D8: CTCTCTAC | E8: N707 | F8: TAGATCGC | G8: S501
A9: 8 | B9: A | C9: A08 | D9: CAGAGAGG | E9: N708 | F9: TAGATCGC | G9: S501
A10: 9 | B10: A | C10: A09 | D10: GCTACGCT | E10: N709 | F10: TAGATCGC | G10: S501
A11: 10 | B11: A | C11: A10 | D11: CGAGGCTG | E11: N710 | F11: TAGATCGC | G11: S501
A12: 11 | B12: A | C12: A11 | D12: AAGAGGCA | E12: N711 | F12: TAGATCGC | G12: S501
A13: 12 | B13: A | C13: A12 | D13: GTAGAGGA | E13: N712 | F13: TAGATCGC | G13: S501
... A385: 384 | B385: D | C385: H12 | D385: CGATCAGT | E385: N724 | F385: AAGGCTAT | G385: S516
