Workbook

Sheet prep_table
A1: sample_num | B1: plate_well | C1: library_name | D1: library_id | E1: requestor | F1: pool | G1: library_kits | H1: library_prep_type | I1: rna_ng_per_ul_qubit | J1: dilution | K1: RIN | L1: conc_after_dilution | M1: comment | N1: ul_h2o | O1: ul_rna | P1: input_ng | Q1: pcr_cycles | R1: index_well | S1: kit_i7 | T1: kit_i5 | U1: sequence_i7 | V1: name_i7 | W1: sequence_i5 | X1: name_i5 | Y1: lib_conc_ng_ul | Z1: ba | AA1: pooling_factor | AB1: ul_pooling
A2: 1 | L2: =I2/J2 -> #DIV/0! | N2: =IF(ISTEXT(polyA_express!$E$2),50-O2,IF(ISTEXT(#REF!),11-O2,IF(ISTEXT(rRNA_Depletion_express!$E$2),11-O2,))) -> 0 | O2: 5 | P2: =+L2*O2 -> #DIV/0! | AA2: =+MAX($Y$2:$Y$97)/Y2 -> #DIV/0! | AB2: =AA2*1 -> #DIV/0!
A3: 2 | L3: =I3/J3 -> #DIV/0! | N3: =IF(ISTEXT(polyA_express!$E$2),50-O3,IF(ISTEXT(#REF!),11-O3,IF(ISTEXT(rRNA_Depletion_express!$E$2),11-O3,))) -> 0 | O3: 5 | P3: =+L3*O3 -> #DIV/0! | AA3: =+MAX($Y$2:$Y$97)/Y3 -> #DIV/0! | AB3: =AA3*1 -> #DIV/0!
A4: 3 | L4: =I4/J4 -> #DIV/0! | N4: =IF(ISTEXT(polyA_express!$E$2),50-O4,IF(ISTEXT(#REF!),11-O4,IF(ISTEXT(rRNA_Depletion_express!$E$2),11-O4,))) -> 0 | O4: 5 | P4: =+L4*O4 -> #DIV/0! | AA4: =+MAX($Y$2:$Y$97)/Y4 -> #DIV/0! | AB4: =AA4*1 -> #DIV/0!
A5: 4 | L5: =I5/J5 -> #DIV/0! | N5: =IF(ISTEXT(polyA_express!$E$2),50-O5,IF(ISTEXT(#REF!),11-O5,IF(ISTEXT(rRNA_Depletion_express!$E$2),11-O5,))) -> 0 | O5: 5 | P5: =+L5*O5 -> #DIV/0! | AA5: =+MAX($Y$2:$Y$97)/Y5 -> #DIV/0! | AB5: =AA5*1 -> #DIV/0!
A6: 5 | L6: =I6/J6 -> #DIV/0! | N6: =IF(ISTEXT(polyA_express!$E$2),50-O6,IF(ISTEXT(#REF!),11-O6,IF(ISTEXT(rRNA_Depletion_express!$E$2),11-O6,))) -> 0 | O6: 5 | P6: =+L6*O6 -> #DIV/0! | AA6: =+MAX($Y$2:$Y$97)/Y6 -> #DIV/0! | AB6: =AA6*1 -> #DIV/0!
A7: 6 | L7: =I7/J7 -> #DIV/0! | N7: =IF(ISTEXT(polyA_express!$E$2),50-O7,IF(ISTEXT(#REF!),11-O7,IF(ISTEXT(rRNA_Depletion_express!$E$2),11-O7,))) -> 0 | O7: 5 | P7: =+L7*O7 -> #DIV/0! | AA7: =+MAX($Y$2:$Y$97)/Y7 -> #DIV/0! | AB7: =AA7*1 -> #DIV/0!
A8: 7 | L8: =I8/J8 -> #DIV/0! | N8: =IF(ISTEXT(polyA_express!$E$2),50-O8,IF(ISTEXT(#REF!),11-O8,IF(ISTEXT(rRNA_Depletion_express!$E$2),11-O8,))) -> 0 | O8: 5 | P8: =+L8*O8 -> #DIV/0! | AA8: =+MAX($Y$2:$Y$97)/Y8 -> #DIV/0! | AB8: =AA8*1 -> #DIV/0!
A9: 8 | L9: =I9/J9 -> #DIV/0! | N9: =IF(ISTEXT(polyA_express!$E$2),50-O9,IF(ISTEXT(#REF!),11-O9,IF(ISTEXT(rRNA_Depletion_express!$E$2),11-O9,))) -> 0 | O9: 5 | P9: =+L9*O9 -> #DIV/0! | AA9: =+MAX($Y$2:$Y$97)/Y9 -> #DIV/0! | AB9: =AA9*1 -> #DIV/0!
A10: 9 | L10: =I10/J10 -> #DIV/0! | N10: =IF(ISTEXT(polyA_express!$E$2),50-O10,IF(ISTEXT(#REF!),11-O10,IF(ISTEXT(rRNA_Depletion_express!$E$2),11-O10,))) -> 0 | O10: 5 | P10: =+L10*O10 -> #DIV/0! | AA10: =+MAX($Y$2:$Y$97)/Y10 -> #DIV/0! | AB10: =AA10*1 -> #DIV/0!
A11: 10 | L11: =I11/J11 -> #DIV/0! | N11: =IF(ISTEXT(polyA_express!$E$2),50-O11,IF(ISTEXT(#REF!),11-O11,IF(ISTEXT(rRNA_Depletion_express!$E$2),11-O11,))) -> 0 | O11: 5 | P11: =+L11*O11 -> #DIV/0! | AA11: =+MAX($Y$2:$Y$97)/Y11 -> #DIV/0! | AB11: =AA11*1 -> #DIV/0!
A12: 11 | L12: =I12/J12 -> #DIV/0! | N12: =IF(ISTEXT(polyA_express!$E$2),50-O12,IF(ISTEXT(#REF!),11-O12,IF(ISTEXT(rRNA_Depletion_express!$E$2),11-O12,))) -> 0 | O12: 5 | P12: =+L12*O12 -> #DIV/0! | AA12: =+MAX($Y$2:$Y$97)/Y12 -> #DIV/0! | AB12: =AA12*1 -> #DIV/0!
A13: 12 | L13: =I13/J13 -> #DIV/0! | N13: =IF(ISTEXT(polyA_express!$E$2),50-O13,IF(ISTEXT(#REF!),11-O13,IF(ISTEXT(rRNA_Depletion_express!$E$2),11-O13,))) -> 0 | O13: 5 | P13: =+L13*O13 -> #DIV/0! | AA13: =+MAX($Y$2:$Y$97)/Y13 -> #DIV/0! | AB13: =AA13*1 -> #DIV/0!
... A97: 96 | L97: =I97/J97 -> #DIV/0! | N97: =IF(ISTEXT(polyA_express!$E$2),50-O97,IF(ISTEXT(#REF!),11-O97,IF(ISTEXT(rRNA_Depletion_express!$E$2),11-O97,))) -> 0 | O97: 5 | P97: =+L97*O97 -> #DIV/0! | AA97: =+MAX($Y$2:$Y$97)/Y97 -> #DIV/0! | AB97: =AA97*1 -> #DIV/0!

Sheet polyA_express
C1: Checklist NEBNext UltraExpress RNA library prep kit poly(A) isolation
A2: Library prep number:
A3: SOP Version: | K3: Indexplate A: | L3: 1
A4: NEBNext UltraExpress™ RNA Library Prep Kit LOT#: | J4: Signature:
A5: NEBNext Multiplex Oligos for Illumina (Unique Dual Index UMI Adaptors RNA Set 1) LOT#:
A6: NEBNext Poly(A) mRNA Magnetic Isolation Module LOT#:
A7: Library person:
A8: Library date:
A9: Comments:
A10: Number of samples COLUMNS: | F10: =MOD(E10,8)=0 -> TRUE | G10: =ROUNDDOWN((E10/8),0) -> 0 | H10: =E10-G10*8 -> 0
A11: Number of samples ROWS: | F11: =MOD($E$11,12)=0 -> TRUE | G11: =ROUNDDOWN(($E$11/12),0) -> 0 | H11: =$E$11-$G$11*12 -> 0
B12: Preparation of working plate
B13: Prepare an working plate with 25 - 250 ng of total RNA in 50µL in the following sheme:
C14: 1 | D14: 2 | E14: 3 | F14: 4 | G14: 5 | H14: 6 | I14: 7 | J14: 8 | K14: 9 | L14: 10 | M14: 11 | N14: 12
B15: A | C15: =IF(ISNUMBER($E$11),prep_table!$C$2,prep_table!$C$2) -> 0 | D15: =IF(ISNUMBER($E$11),prep_table!$C$3,prep_table!$C$10) -> 0 | E15: =IF(ISNUMBER($E$11),prep_table!$C$4,prep_table!$C$18) -> 0 | F15: =IF(ISNUMBER($E$11),prep_table!$C$5,prep_table!$C$26) -> 0 | G15: =IF(ISNUMBER($E$11),prep_table!$C$6,prep_table!$C$34) -> 0 | H15: =IF(ISNUMBER($E$11),prep_table!$C$7,prep_table!$C$42) -> 0 | I15: =IF(ISNUMBER($E$11),prep_table!$C$8,prep_table!$C$50) -> 0 | J15: =IF(ISNUMBER($E$11),prep_table!$C$9,prep_table!$C$58) -> 0 | K15: =IF(ISNUMBER($E$11),prep_table!$C$10,prep_table!$C$66) -> 0 | L15: =IF(ISNUMBER($E$11),prep_table!$C$11,prep_table!$C$74) -> 0 | M15: =IF(ISNUMBER($E$11),prep_table!$C$12,prep_table!$C$82) -> 0 | N15: =IF(ISNUMBER($E$11),prep_table!$C$13,prep_table!$C$90) -> 0
B16: B | C16: =IF(ISNUMBER($E$11),prep_table!$C$14,prep_table!$C$3) -> 0 | D16: =IF(ISNUMBER($E$11),prep_table!$C$15,prep_table!$C$11) -> 0 | E16: =IF(ISNUMBER($E$11),prep_table!$C$16,prep_table!$C$19) -> 0 | F16: =IF(ISNUMBER($E$11),prep_table!$C$17,prep_table!$C$27) -> 0 | G16: =IF(ISNUMBER($E$11),prep_table!$C$18,prep_table!$C$35) -> 0 | H16: =IF(ISNUMBER($E$11),prep_table!$C$19,prep_table!$C$43) -> 0 | I16: =IF(ISNUMBER($E$11),prep_table!$C$20,prep_table!$C$51) -> 0 | J16: =IF(ISNUMBER($E$11),prep_table!$C$21,prep_table!$C$59) -> 0 | K16: =IF(ISNUMBER($E$11),prep_table!$C$22,prep_table!$C$67) -> 0 | L16: =IF(ISNUMBER($E$11),prep_table!$C$23,prep_table!$C$75) -> 0 | M16: =IF(ISNUMBER($E$11),prep_table!$C$24,prep_table!$C$83) -> 0 | N16: =IF(ISNUMBER($E$11),prep_table!$C$25,prep_table!$C$91) -> 0
B17: C | C17: =IF(ISNUMBER($E$11),prep_table!$C$26,prep_table!$C$4) -> 0 | D17: =IF(ISNUMBER($E$11),prep_table!$C$27,prep_table!$C$12) -> 0 | E17: =IF(ISNUMBER($E$11),prep_table!$C$28,prep_table!$C$20) -> 0 | F17: =IF(ISNUMBER($E$11),prep_table!$C$29,prep_table!$C$28) -> 0 | G17: =IF(ISNUMBER($E$11),prep_table!$C$30,prep_table!$C$36) -> 0 | H17: =IF(ISNUMBER($E$11),prep_table!$C$31,prep_table!$C$44) -> 0 | I17: =IF(ISNUMBER($E$11),prep_table!$C$32,prep_table!$C$52) -> 0 | J17: =IF(ISNUMBER($E$11),prep_table!$C$33,prep_table!$C$60) -> 0 | K17: =IF(ISNUMBER($E$11),prep_table!$C$34,prep_table!$C$68) -> 0 | L17: =IF(ISNUMBER($E$11),prep_table!$C$35,prep_table!$C$76) -> 0 | M17: =IF(ISNUMBER($E$11),prep_table!$C$36,prep_table!$C$84) -> 0 | N17: =IF(ISNUMBER($E$11),prep_table!$C$37,prep_table!$C$92) -> 0
B18: D | C18: =IF(ISNUMBER($E$11),prep_table!$C$38,prep_table!$C$5) -> 0 | D18: =IF(ISNUMBER($E$11),prep_table!$C$39,prep_table!$C$13) -> 0 | E18: =IF(ISNUMBER($E$11),prep_table!$C$40,prep_table!$C$21) -> 0 | F18: =IF(ISNUMBER($E$11),prep_table!$C$41,prep_table!$C$29) -> 0 | G18: =IF(ISNUMBER($E$11),prep_table!$C$42,prep_table!$C$37) -> 0 | H18: =IF(ISNUMBER($E$11),prep_table!$C$43,prep_table!$C$45) -> 0 | I18: =IF(ISNUMBER($E$11),prep_table!$C$44,prep_table!$C$53) -> 0 | J18: =IF(ISNUMBER($E$11),prep_table!$C$45,prep_table!$C$61) -> 0 | K18: =IF(ISNUMBER($E$11),prep_table!$C$46,prep_table!$C$69) -> 0 | L18: =IF(ISNUMBER($E$11),prep_table!$C$47,prep_table!$C$77) -> 0 | M18: =IF(ISNUMBER($E$11),prep_table!$C$48,prep_table!$C$85) -> 0 | N18: =IF(ISNUMBER($E$11),prep_table!$C$49,prep_table!$C$93) -> 0
B19: E | C19: =IF(ISNUMBER($E$11),prep_table!$C$50,prep_table!$C$6) -> 0 | D19: =IF(ISNUMBER($E$11),prep_table!$C$51,prep_table!$C$14) -> 0 | E19: =IF(ISNUMBER($E$11),prep_table!$C$52,prep_table!$C$22) -> 0 | F19: =IF(ISNUMBER($E$11),prep_table!$C$53,prep_table!$C$30) -> 0 | G19: =IF(ISNUMBER($E$11),prep_table!$C$54,prep_table!$C$38) -> 0 | H19: =IF(ISNUMBER($E$11),prep_table!$C$55,prep_table!$C$46) -> 0 | I19: =IF(ISNUMBER($E$11),prep_table!$C$56,prep_table!$C$54) -> 0 | J19: =IF(ISNUMBER($E$11),prep_table!$C$57,prep_table!$C$62) -> 0 | K19: =IF(ISNUMBER($E$11),prep_table!$C$58,prep_table!$C$70) -> 0 | L19: =IF(ISNUMBER($E$11),prep_table!$C$59,prep_table!$C$78) -> 0 | M19: =IF(ISNUMBER($E$11),prep_table!$C$60,prep_table!$C$86) -> 0 | N19: =IF(ISNUMBER($E$11),prep_table!$C$61,prep_table!$C$94) -> 0
B20: F | C20: =IF(ISNUMBER($E$11),prep_table!$C$62,prep_table!$C$7) -> 0 | D20: =IF(ISNUMBER($E$11),prep_table!$C$63,prep_table!$C$15) -> 0 | E20: =IF(ISNUMBER($E$11),prep_table!$C$64,prep_table!$C$23) -> 0 | F20: =IF(ISNUMBER($E$11),prep_table!$C$65,prep_table!$C$31) -> 0 | G20: =IF(ISNUMBER($E$11),prep_table!$C$66,prep_table!$C$39) -> 0 | H20: =IF(ISNUMBER($E$11),prep_table!$C$67,prep_table!$C$47) -> 0 | I20: =IF(ISNUMBER($E$11),prep_table!$C$68,prep_table!$C$55) -> 0 | J20: =IF(ISNUMBER($E$11),prep_table!$C$69,prep_table!$C$63) -> 0 | K20: =IF(ISNUMBER($E$11),prep_table!$C$70,prep_table!$C$71) -> 0 | L20: =IF(ISNUMBER($E$11),prep_table!$C$71,prep_table!$C$79) -> 0 | M20: =IF(ISNUMBER($E$11),prep_table!$C$72,prep_table!$C$87) -> 0 | N20: =IF(ISNUMBER($E$11),prep_table!$C$73,prep_table!$C$95) -> 0
B21: G | C21: =IF(ISNUMBER($E$11),prep_table!$C$74,prep_table!$C$8) -> 0 | D21: =IF(ISNUMBER($E$11),prep_table!$C$75,prep_table!$C$16) -> 0 | E21: =IF(ISNUMBER($E$11),prep_table!$C$76,prep_table!$C$24) -> 0 | F21: =IF(ISNUMBER($E$11),prep_table!$C$77,prep_table!$C$32) -> 0 | G21: =IF(ISNUMBER($E$11),prep_table!$C$78,prep_table!$C$40) -> 0 | H21: =IF(ISNUMBER($E$11),prep_table!$C$79,prep_table!$C$48) -> 0 | I21: =IF(ISNUMBER($E$11),prep_table!$C$80,prep_table!$C$56) -> 0 | J21: =IF(ISNUMBER($E$11),prep_table!$C$81,prep_table!$C$64) -> 0 | K21: =IF(ISNUMBER($E$11),prep_table!$C$82,prep_table!$C$72) -> 0 | L21: =IF(ISNUMBER($E$11),prep_table!$C$83,prep_table!$C$80) -> 0 | M21: =IF(ISNUMBER($E$11),prep_table!$C$84,prep_table!$C$88) -> 0 | N21: =IF(ISNUMBER($E$11),prep_table!$C$85,prep_table!$C$96) -> 0
B22: H | C22: =IF(ISNUMBER($E$11),prep_table!$C$86,prep_table!$C$9) -> 0 | D22: =IF(ISNUMBER($E$11),prep_table!$C$87,prep_table!$C$17) -> 0 | E22: =IF(ISNUMBER($E$11),prep_table!$C$88,prep_table!$C$25) -> 0 | F22: =IF(ISNUMBER($E$11),prep_table!$C$89,prep_table!$C$33) -> 0 | G22: =IF(ISNUMBER($E$11),prep_table!$C$90,prep_table!$C$41) -> 0 | H22: =IF(ISNUMBER($E$11),prep_table!$C$91,prep_table!$C$49) -> 0 | I22: =IF(ISNUMBER($E$11),prep_table!$C$92,prep_table!$C$57) -> 0 | J22: =IF(ISNUMBER($E$11),prep_table!$C$93,prep_table!$C$65) -> 0 | K22: =IF(ISNUMBER($E$11),prep_table!$C$94,prep_table!$C$73) -> 0 | L22: =IF(ISNUMBER($E$11),prep_table!$C$95,prep_table!$C$81) -> 0 | M22: =IF(ISNUMBER($E$11),prep_table!$C$96,prep_table!$C$89) -> 0 | N22: =IF(ISNUMBER($E$11),prep_table!$C$97,prep_table!$C$97) -> 0
A23: µL RNA: | C23: 1 | D23: 2 | E23: 3 | F23: 4 | G23: 5 | H23: 6 | I23: 7 | J23: 8 | K23: 9 | L23: 10 | M23: 11 | N23: 12
B24: A | C24: =IF(ISNUMBER($E$11),prep_table!$O$2,prep_table!$O$2) -> 5 | D24: =IF(ISNUMBER($E$11),prep_table!$O$3,prep_table!$O$10) -> 5 | E24: =IF(ISNUMBER($E$11),prep_table!$O$4,prep_table!$O$18) -> 5 | F24: =IF(ISNUMBER($E$11),prep_table!$O$5,prep_table!$O$26) -> 5 | G24: =IF(ISNUMBER($E$11),prep_table!$O$6,prep_table!$O$34) -> 5 | H24: =IF(ISNUMBER($E$11),prep_table!$O$7,prep_table!$O$42) -> 5 | I24: =IF(ISNUMBER($E$11),prep_table!$O$8,prep_table!$O$50) -> 5 | J24: =IF(ISNUMBER($E$11),prep_table!$O$9,prep_table!$O$58) -> 5 | K24: =IF(ISNUMBER($E$11),prep_table!$O$10,prep_table!$O$66) -> 5 | L24: =IF(ISNUMBER($E$11),prep_table!$O$11,prep_table!$O$74) -> 5 | M24: =IF(ISNUMBER($E$11),prep_table!$O$12,prep_table!$O$82) -> 5 | N24: =IF(ISNUMBER($E$11),prep_table!$O$13,prep_table!$O$90) -> 5
B25: B | C25: =IF(ISNUMBER($E$11),prep_table!$O$14,prep_table!$O$3) -> 5 | D25: =IF(ISNUMBER($E$11),prep_table!$O$15,prep_table!$O$11) -> 5 | E25: =IF(ISNUMBER($E$11),prep_table!$O$16,prep_table!$O$19) -> 5 | F25: =IF(ISNUMBER($E$11),prep_table!$O$17,prep_table!$O$27) -> 5 | G25: =IF(ISNUMBER($E$11),prep_table!$O$18,prep_table!$O$35) -> 5 | H25: =IF(ISNUMBER($E$11),prep_table!$O$19,prep_table!$O$43) -> 5 | I25: =IF(ISNUMBER($E$11),prep_table!$O$20,prep_table!$O$51) -> 5 | J25: =IF(ISNUMBER($E$11),prep_table!$O$21,prep_table!$O$59) -> 5 | K25: =IF(ISNUMBER($E$11),prep_table!$O$22,prep_table!$O$67) -> 5 | L25: =IF(ISNUMBER($E$11),prep_table!$O$23,prep_table!$O$75) -> 5 | M25: =IF(ISNUMBER($E$11),prep_table!$O$24,prep_table!$O$83) -> 5 | N25: =IF(ISNUMBER($E$11),prep_table!$O$25,prep_table!$O$91) -> 5
B26: C | C26: =IF(ISNUMBER($E$11),prep_table!$O$26,prep_table!$O$4) -> 5 | D26: =IF(ISNUMBER($E$11),prep_table!$O$27,prep_table!$O$12) -> 5 | E26: =IF(ISNUMBER($E$11),prep_table!$O$28,prep_table!$O$20) -> 5 | F26: =IF(ISNUMBER($E$11),prep_table!$O$29,prep_table!$O$28) -> 5 | G26: =IF(ISNUMBER($E$11),prep_table!$O$30,prep_table!$O$36) -> 5 | H26: =IF(ISNUMBER($E$11),prep_table!$O$31,prep_table!$O$44) -> 5 | I26: =IF(ISNUMBER($E$11),prep_table!$O$32,prep_table!$O$52) -> 5 | J26: =IF(ISNUMBER($E$11),prep_table!$O$33,prep_table!$O$60) -> 5 | K26: =IF(ISNUMBER($E$11),prep_table!$O$34,prep_table!$O$68) -> 5 | L26: =IF(ISNUMBER($E$11),prep_table!$O$35,prep_table!$O$76) -> 5 | M26: =IF(ISNUMBER($E$11),prep_table!$O$36,prep_table!$O$84) -> 5 | N26: =IF(ISNUMBER($E$11),prep_table!$O$37,prep_table!$O$92) -> 5
B27: D | C27: =IF(ISNUMBER($E$11),prep_table!$O$38,prep_table!$O$5) -> 5 | D27: =IF(ISNUMBER($E$11),prep_table!$O$39,prep_table!$O$13) -> 5 | E27: =IF(ISNUMBER($E$11),prep_table!$O$40,prep_table!$O$21) -> 5 | F27: =IF(ISNUMBER($E$11),prep_table!$O$41,prep_table!$O$29) -> 5 | G27: =IF(ISNUMBER($E$11),prep_table!$O$42,prep_table!$O$37) -> 5 | H27: =IF(ISNUMBER($E$11),prep_table!$O$43,prep_table!$O$45) -> 5 | I27: =IF(ISNUMBER($E$11),prep_table!$O$44,prep_table!$O$53) -> 5 | J27: =IF(ISNUMBER($E$11),prep_table!$O$45,prep_table!$O$61) -> 5 | K27: =IF(ISNUMBER($E$11),prep_table!$O$46,prep_table!$O$69) -> 5 | L27: =IF(ISNUMBER($E$11),prep_table!$O$47,prep_table!$O$77) -> 5 | M27: =IF(ISNUMBER($E$11),prep_table!$O$48,prep_table!$O$85) -> 5 | N27: =IF(ISNUMBER($E$11),prep_table!$O$49,prep_table!$O$93) -> 5
B28: E | C28: =IF(ISNUMBER($E$11),prep_table!$O$50,prep_table!$O$6) -> 5 | D28: =IF(ISNUMBER($E$11),prep_table!$O$51,prep_table!$O$14) -> 5 | E28: =IF(ISNUMBER($E$11),prep_table!$O$52,prep_table!$O$22) -> 5 | F28: =IF(ISNUMBER($E$11),prep_table!$O$53,prep_table!$O$30) -> 5 | G28: =IF(ISNUMBER($E$11),prep_table!$O$54,prep_table!$O$38) -> 5 | H28: =IF(ISNUMBER($E$11),prep_table!$O$55,prep_table!$O$46) -> 5 | I28: =IF(ISNUMBER($E$11),prep_table!$O$56,prep_table!$O$54) -> 5 | J28: =IF(ISNUMBER($E$11),prep_table!$O$57,prep_table!$O$62) -> 5 | K28: =IF(ISNUMBER($E$11),prep_table!$O$58,prep_table!$O$70) -> 5 | L28: =IF(ISNUMBER($E$11),prep_table!$O$59,prep_table!$O$78) -> 5 | M28: =IF(ISNUMBER($E$11),prep_table!$O$60,prep_table!$O$86) -> 5 | N28: =IF(ISNUMBER($E$11),prep_table!$O$61,prep_table!$O$94) -> 5
B29: F | C29: =IF(ISNUMBER($E$11),prep_table!$O$62,prep_table!$O$7) -> 5 | D29: =IF(ISNUMBER($E$11),prep_table!$O$63,prep_table!$O$15) -> 5 | E29: =IF(ISNUMBER($E$11),prep_table!$O$64,prep_table!$O$23) -> 5 | F29: =IF(ISNUMBER($E$11),prep_table!$O$65,prep_table!$O$31) -> 5 | G29: =IF(ISNUMBER($E$11),prep_table!$O$66,prep_table!$O$39) -> 5 | H29: =IF(ISNUMBER($E$11),prep_table!$O$67,prep_table!$O$47) -> 5 | I29: =IF(ISNUMBER($E$11),prep_table!$O$68,prep_table!$O$55) -> 5 | J29: =IF(ISNUMBER($E$11),prep_table!$O$69,prep_table!$O$63) -> 5 | K29: =IF(ISNUMBER($E$11),prep_table!$O$70,prep_table!$O$71) -> 5 | L29: =IF(ISNUMBER($E$11),prep_table!$O$71,prep_table!$O$79) -> 5 | M29: =IF(ISNUMBER($E$11),prep_table!$O$72,prep_table!$O$87) -> 5 | N29: =IF(ISNUMBER($E$11),prep_table!$O$73,prep_table!$O$95) -> 5
B30: G | C30: =IF(ISNUMBER($E$11),prep_table!$O$74,prep_table!$O$8) -> 5 | D30: =IF(ISNUMBER($E$11),prep_table!$O$75,prep_table!$O$16) -> 5 | E30: =IF(ISNUMBER($E$11),prep_table!$O$76,prep_table!$O$24) -> 5 | F30: =IF(ISNUMBER($E$11),prep_table!$O$77,prep_table!$O$32) -> 5 | G30: =IF(ISNUMBER($E$11),prep_table!$O$78,prep_table!$O$40) -> 5 | H30: =IF(ISNUMBER($E$11),prep_table!$O$79,prep_table!$O$48) -> 5 | I30: =IF(ISNUMBER($E$11),prep_table!$O$80,prep_table!$O$56) -> 5 | J30: =IF(ISNUMBER($E$11),prep_table!$O$81,prep_table!$O$64) -> 5 | K30: =IF(ISNUMBER($E$11),prep_table!$O$82,prep_table!$O$72) -> 5 | L30: =IF(ISNUMBER($E$11),prep_table!$O$83,prep_table!$O$80) -> 5 | M30: =IF(ISNUMBER($E$11),prep_table!$O$84,prep_table!$O$88) -> 5 | N30: =IF(ISNUMBER($E$11),prep_table!$O$85,prep_table!$O$96) -> 5
B31: H | C31: =IF(ISNUMBER($E$11),prep_table!$O$86,prep_table!$O$9) -> 5 | D31: =IF(ISNUMBER($E$11),prep_table!$O$87,prep_table!$O$17) -> 5 | E31: =IF(ISNUMBER($E$11),prep_table!$O$88,prep_table!$O$25) -> 5 | F31: =IF(ISNUMBER($E$11),prep_table!$O$89,prep_table!$O$33) -> 5 | G31: =IF(ISNUMBER($E$11),prep_table!$O$90,prep_table!$O$41) -> 5 | H31: =IF(ISNUMBER($E$11),prep_table!$O$91,prep_table!$O$49) -> 5 | I31: =IF(ISNUMBER($E$11),prep_table!$O$92,prep_table!$O$57) -> 5 | J31: =IF(ISNUMBER($E$11),prep_table!$O$93,prep_table!$O$65) -> 5 | K31: =IF(ISNUMBER($E$11),prep_table!$O$94,prep_table!$O$73) -> 5 | L31: =IF(ISNUMBER($E$11),prep_table!$O$95,prep_table!$O$81) -> 5 | M31: =IF(ISNUMBER($E$11),prep_table!$O$96,prep_table!$O$89) -> 5 | N31: =IF(ISNUMBER($E$11),prep_table!$O$97,prep_table!$O$97) -> 5
A32: µL water: | C32: 1 | D32: 2 | E32: 3 | F32: 4 | G32: 5 | H32: 6 | I32: 7 | J32: 8 | K32: 9 | L32: 10 | M32: 11 | N32: 12
B33: A | C33: =IF(ISNUMBER($E$11),prep_table!$N$2,prep_table!$N$2) -> 0 | D33: =IF(ISNUMBER($E$11),prep_table!$N$3,prep_table!$N$10) -> 0 | E33: =IF(ISNUMBER($E$11),prep_table!$N$4,prep_table!$N$18) -> 0 | F33: =IF(ISNUMBER($E$11),prep_table!$N$5,prep_table!$N$26) -> 0 | G33: =IF(ISNUMBER($E$11),prep_table!$N$6,prep_table!$N$34) -> 0 | H33: =IF(ISNUMBER($E$11),prep_table!$N$7,prep_table!$N$42) -> 0 | I33: =IF(ISNUMBER($E$11),prep_table!$N$8,prep_table!$N$50) -> 0 | J33: =IF(ISNUMBER($E$11),prep_table!$N$9,prep_table!$N$58) -> 0 | K33: =IF(ISNUMBER($E$11),prep_table!$N$10,prep_table!$N$66) -> 0 | L33: =IF(ISNUMBER($E$11),prep_table!$N$11,prep_table!$N$74) -> 0 | M33: =IF(ISNUMBER($E$11),prep_table!$N$12,prep_table!$N$82) -> 0 | N33: =IF(ISNUMBER($E$11),prep_table!$N$13,prep_table!$N$90) -> 0
B34: B | C34: =IF(ISNUMBER($E$11),prep_table!$N$14,prep_table!$N$3) -> 0 | D34: =IF(ISNUMBER($E$11),prep_table!$N$15,prep_table!$N$11) -> 0 | E34: =IF(ISNUMBER($E$11),prep_table!$N$16,prep_table!$N$19) -> 0 | F34: =IF(ISNUMBER($E$11),prep_table!$N$17,prep_table!$N$27) -> 0 | G34: =IF(ISNUMBER($E$11),prep_table!$N$18,prep_table!$N$35) -> 0 | H34: =IF(ISNUMBER($E$11),prep_table!$N$19,prep_table!$N$43) -> 0 | I34: =IF(ISNUMBER($E$11),prep_table!$N$20,prep_table!$N$51) -> 0 | J34: =IF(ISNUMBER($E$11),prep_table!$N$21,prep_table!$N$59) -> 0 | K34: =IF(ISNUMBER($E$11),prep_table!$N$22,prep_table!$N$67) -> 0 | L34: =IF(ISNUMBER($E$11),prep_table!$N$23,prep_table!$N$75) -> 0 | M34: =IF(ISNUMBER($E$11),prep_table!$N$24,prep_table!$N$83) -> 0 | N34: =IF(ISNUMBER($E$11),prep_table!$N$25,prep_table!$N$91) -> 0
B35: C | C35: =IF(ISNUMBER($E$11),prep_table!$N$26,prep_table!$N$4) -> 0 | D35: =IF(ISNUMBER($E$11),prep_table!$N$27,prep_table!$N$12) -> 0 | E35: =IF(ISNUMBER($E$11),prep_table!$N$28,prep_table!$N$20) -> 0 | F35: =IF(ISNUMBER($E$11),prep_table!$N$29,prep_table!$N$28) -> 0 | G35: =IF(ISNUMBER($E$11),prep_table!$N$30,prep_table!$N$36) -> 0 | H35: =IF(ISNUMBER($E$11),prep_table!$N$31,prep_table!$N$44) -> 0 | I35: =IF(ISNUMBER($E$11),prep_table!$N$32,prep_table!$N$52) -> 0 | J35: =IF(ISNUMBER($E$11),prep_table!$N$33,prep_table!$N$60) -> 0 | K35: =IF(ISNUMBER($E$11),prep_table!$N$34,prep_table!$N$68) -> 0 | L35: =IF(ISNUMBER($E$11),prep_table!$N$35,prep_table!$N$76) -> 0 | M35: =IF(ISNUMBER($E$11),prep_table!$N$36,prep_table!$N$84) -> 0 | N35: =IF(ISNUMBER($E$11),prep_table!$N$37,prep_table!$N$92) -> 0
B36: D | C36: =IF(ISNUMBER($E$11),prep_table!$N$38,prep_table!$N$5) -> 0 | D36: =IF(ISNUMBER($E$11),prep_table!$N$39,prep_table!$N$13) -> 0 | E36: =IF(ISNUMBER($E$11),prep_table!$N$40,prep_table!$N$21) -> 0 | F36: =IF(ISNUMBER($E$11),prep_table!$N$41,prep_table!$N$29) -> 0 | G36: =IF(ISNUMBER($E$11),prep_table!$N$42,prep_table!$N$37) -> 0 | H36: =IF(ISNUMBER($E$11),prep_table!$N$43,prep_table!$N$45) -> 0 | I36: =IF(ISNUMBER($E$11),prep_table!$N$44,prep_table!$N$53) -> 0 | J36: =IF(ISNUMBER($E$11),prep_table!$N$45,prep_table!$N$61) -> 0 | K36: =IF(ISNUMBER($E$11),prep_table!$N$46,prep_table!$N$69) -> 0 | L36: =IF(ISNUMBER($E$11),prep_table!$N$47,prep_table!$N$77) -> 0 | M36: =IF(ISNUMBER($E$11),prep_table!$N$48,prep_table!$N$85) -> 0 | N36: =IF(ISNUMBER($E$11),prep_table!$N$49,prep_table!$N$93) -> 0
B37: E | C37: =IF(ISNUMBER($E$11),prep_table!$N$50,prep_table!$N$6) -> 0 | D37: =IF(ISNUMBER($E$11),prep_table!$N$51,prep_table!$N$14) -> 0 | E37: =IF(ISNUMBER($E$11),prep_table!$N$52,prep_table!$N$22) -> 0 | F37: =IF(ISNUMBER($E$11),prep_table!$N$53,prep_table!$N$30) -> 0 | G37: =IF(ISNUMBER($E$11),prep_table!$N$54,prep_table!$N$38) -> 0 | H37: =IF(ISNUMBER($E$11),prep_table!$N$55,prep_table!$N$46) -> 0 | I37: =IF(ISNUMBER($E$11),prep_table!$N$56,prep_table!$N$54) -> 0 | J37: =IF(ISNUMBER($E$11),prep_table!$N$57,prep_table!$N$62) -> 0 | K37: =IF(ISNUMBER($E$11),prep_table!$N$58,prep_table!$N$70) -> 0 | L37: =IF(ISNUMBER($E$11),prep_table!$N$59,prep_table!$N$78) -> 0 | M37: =IF(ISNUMBER($E$11),prep_table!$N$60,prep_table!$N$86) -> 0 | N37: =IF(ISNUMBER($E$11),prep_table!$N$61,prep_table!$N$94) -> 0
B38: F | C38: =IF(ISNUMBER($E$11),prep_table!$N$62,prep_table!$N$7) -> 0 | D38: =IF(ISNUMBER($E$11),prep_table!$N$63,prep_table!$N$15) -> 0 | E38: =IF(ISNUMBER($E$11),prep_table!$N$64,prep_table!$N$23) -> 0 | F38: =IF(ISNUMBER($E$11),prep_table!$N$65,prep_table!$N$31) -> 0 | G38: =IF(ISNUMBER($E$11),prep_table!$N$66,prep_table!$N$39) -> 0 | H38: =IF(ISNUMBER($E$11),prep_table!$N$67,prep_table!$N$47) -> 0 | I38: =IF(ISNUMBER($E$11),prep_table!$N$68,prep_table!$N$55) -> 0 | J38: =IF(ISNUMBER($E$11),prep_table!$N$69,prep_table!$N$63) -> 0 | K38: =IF(ISNUMBER($E$11),prep_table!$N$70,prep_table!$N$71) -> 0 | L38: =IF(ISNUMBER($E$11),prep_table!$N$71,prep_table!$N$79) -> 0 | M38: =IF(ISNUMBER($E$11),prep_table!$N$72,prep_table!$N$87) -> 0 | N38: =IF(ISNUMBER($E$11),prep_table!$N$73,prep_table!$N$95) -> 0
B39: G | C39: =IF(ISNUMBER($E$11),prep_table!$N$74,prep_table!$N$8) -> 0 | D39: =IF(ISNUMBER($E$11),prep_table!$N$75,prep_table!$N$16) -> 0 | E39: =IF(ISNUMBER($E$11),prep_table!$N$76,prep_table!$N$24) -> 0 | F39: =IF(ISNUMBER($E$11),prep_table!$N$77,prep_table!$N$32) -> 0 | G39: =IF(ISNUMBER($E$11),prep_table!$N$78,prep_table!$N$40) -> 0 | H39: =IF(ISNUMBER($E$11),prep_table!$N$79,prep_table!$N$48) -> 0 | I39: =IF(ISNUMBER($E$11),prep_table!$N$80,prep_table!$N$56) -> 0 | J39: =IF(ISNUMBER($E$11),prep_table!$N$81,prep_table!$N$64) -> 0 | K39: =IF(ISNUMBER($E$11),prep_table!$N$82,prep_table!$N$72) -> 0 | L39: =IF(ISNUMBER($E$11),prep_table!$N$83,prep_table!$N$80) -> 0 | M39: =IF(ISNUMBER($E$11),prep_table!$N$84,prep_table!$N$88) -> 0 | N39: =IF(ISNUMBER($E$11),prep_table!$N$85,prep_table!$N$96) -> 0
B40: H | C40: =IF(ISNUMBER($E$11),prep_table!$N$86,prep_table!$N$9) -> 0 | D40: =IF(ISNUMBER($E$11),prep_table!$N$87,prep_table!$N$17) -> 0 | E40: =IF(ISNUMBER($E$11),prep_table!$N$88,prep_table!$N$25) -> 0 | F40: =IF(ISNUMBER($E$11),prep_table!$N$89,prep_table!$N$33) -> 0 | G40: =IF(ISNUMBER($E$11),prep_table!$N$90,prep_table!$N$41) -> 0 | H40: =IF(ISNUMBER($E$11),prep_table!$N$91,prep_table!$N$49) -> 0 | I40: =IF(ISNUMBER($E$11),prep_table!$N$92,prep_table!$N$57) -> 0 | J40: =IF(ISNUMBER($E$11),prep_table!$N$93,prep_table!$N$65) -> 0 | K40: =IF(ISNUMBER($E$11),prep_table!$N$94,prep_table!$N$73) -> 0 | L40: =IF(ISNUMBER($E$11),prep_table!$N$95,prep_table!$N$81) -> 0 | M40: =IF(ISNUMBER($E$11),prep_table!$N$96,prep_table!$N$89) -> 0 | N40: =IF(ISNUMBER($E$11),prep_table!$N$97,prep_table!$N$97) -> 0
...

Sheet rRNA_Depletion_express
C1: Checklist NEBNext UltraExpress RNA library prep kit rRNA Depletion v2 Rows
A2: Library prep number:
A3: SOP Version: | K3: Indexplate A: | L3: 1
A4: NEBNext UltraExpress RNA Library Prep Kit LOT#: | J4: Signature:
A5: NEBNext Multiplex Oligos for Illumina (Unique Dual Index UMI Adaptors RNA Set 1) LOT#:
A6: NEBNext rRNA Depletion Kit v2 (Human/Mouse/Rat) LOT#:
A7: Library person:
A8: Library date:
A9: Comments:
A10: Number of samples COLUMS: | E10: 16 | F10: =MOD($E$10,8)=0 -> TRUE | G10: =ROUNDDOWN(($E$10/8),0) -> 2 | H10: =$E$10-$G$10*8 -> 0
A11: Number of samples ROWS: | F11: =MOD($E$11,12)=0 -> TRUE | G11: =ROUNDDOWN(($E$11/12),0) -> 0 | H11: =$E$11-$G$11*12 -> 0
B12: Preparation of working plate
B13: Prepare an working plate with 25ng - 250ng of total RNA in 11µL in the following sheme:
C14: 1 | D14: 2 | E14: 3 | F14: 4 | G14: 5 | H14: 6 | I14: 7 | J14: 8 | K14: 9 | L14: 10 | M14: 11 | N14: 12
B15: A | C15: =IF(ISNUMBER($E$11),prep_table!$C$2,prep_table!$C$2) -> 0 | D15: =IF(ISNUMBER($E$11),prep_table!$C$3,prep_table!$C$10) -> 0 | E15: =IF(ISNUMBER($E$11),prep_table!$C$4,prep_table!$C$18) -> 0 | F15: =IF(ISNUMBER($E$11),prep_table!$C$5,prep_table!$C$26) -> 0 | G15: =IF(ISNUMBER($E$11),prep_table!$C$6,prep_table!$C$34) -> 0 | H15: =IF(ISNUMBER($E$11),prep_table!$C$7,prep_table!$C$42) -> 0 | I15: =IF(ISNUMBER($E$11),prep_table!$C$8,prep_table!$C$50) -> 0 | J15: =IF(ISNUMBER($E$11),prep_table!$C$9,prep_table!$C$58) -> 0 | K15: =IF(ISNUMBER($E$11),prep_table!$C$10,prep_table!$C$66) -> 0 | L15: =IF(ISNUMBER($E$11),prep_table!$C$11,prep_table!$C$74) -> 0 | M15: =IF(ISNUMBER($E$11),prep_table!$C$12,prep_table!$C$82) -> 0 | N15: =IF(ISNUMBER($E$11),prep_table!$C$13,prep_table!$C$90) -> 0
B16: B | C16: =IF(ISNUMBER($E$11),prep_table!$C$14,prep_table!$C$3) -> 0 | D16: =IF(ISNUMBER($E$11),prep_table!$C$15,prep_table!$C$11) -> 0 | E16: =IF(ISNUMBER($E$11),prep_table!$C$16,prep_table!$C$19) -> 0 | F16: =IF(ISNUMBER($E$11),prep_table!$C$17,prep_table!$C$27) -> 0 | G16: =IF(ISNUMBER($E$11),prep_table!$C$18,prep_table!$C$35) -> 0 | H16: =IF(ISNUMBER($E$11),prep_table!$C$19,prep_table!$C$43) -> 0 | I16: =IF(ISNUMBER($E$11),prep_table!$C$20,prep_table!$C$51) -> 0 | J16: =IF(ISNUMBER($E$11),prep_table!$C$21,prep_table!$C$59) -> 0 | K16: =IF(ISNUMBER($E$11),prep_table!$C$22,prep_table!$C$67) -> 0 | L16: =IF(ISNUMBER($E$11),prep_table!$C$23,prep_table!$C$75) -> 0 | M16: =IF(ISNUMBER($E$11),prep_table!$C$24,prep_table!$C$83) -> 0 | N16: =IF(ISNUMBER($E$11),prep_table!$C$25,prep_table!$C$91) -> 0
B17: C | C17: =IF(ISNUMBER($E$11),prep_table!$C$26,prep_table!$C$4) -> 0 | D17: =IF(ISNUMBER($E$11),prep_table!$C$27,prep_table!$C$12) -> 0 | E17: =IF(ISNUMBER($E$11),prep_table!$C$28,prep_table!$C$20) -> 0 | F17: =IF(ISNUMBER($E$11),prep_table!$C$29,prep_table!$C$28) -> 0 | G17: =IF(ISNUMBER($E$11),prep_table!$C$30,prep_table!$C$36) -> 0 | H17: =IF(ISNUMBER($E$11),prep_table!$C$31,prep_table!$C$44) -> 0 | I17: =IF(ISNUMBER($E$11),prep_table!$C$32,prep_table!$C$52) -> 0 | J17: =IF(ISNUMBER($E$11),prep_table!$C$33,prep_table!$C$60) -> 0 | K17: =IF(ISNUMBER($E$11),prep_table!$C$34,prep_table!$C$68) -> 0 | L17: =IF(ISNUMBER($E$11),prep_table!$C$35,prep_table!$C$76) -> 0 | M17: =IF(ISNUMBER($E$11),prep_table!$C$36,prep_table!$C$84) -> 0 | N17: =IF(ISNUMBER($E$11),prep_table!$C$37,prep_table!$C$92) -> 0
B18: D | C18: =IF(ISNUMBER($E$11),prep_table!$C$38,prep_table!$C$5) -> 0 | D18: =IF(ISNUMBER($E$11),prep_table!$C$39,prep_table!$C$13) -> 0 | E18: =IF(ISNUMBER($E$11),prep_table!$C$40,prep_table!$C$21) -> 0 | F18: =IF(ISNUMBER($E$11),prep_table!$C$41,prep_table!$C$29) -> 0 | G18: =IF(ISNUMBER($E$11),prep_table!$C$42,prep_table!$C$37) -> 0 | H18: =IF(ISNUMBER($E$11),prep_table!$C$43,prep_table!$C$45) -> 0 | I18: =IF(ISNUMBER($E$11),prep_table!$C$44,prep_table!$C$53) -> 0 | J18: =IF(ISNUMBER($E$11),prep_table!$C$45,prep_table!$C$61) -> 0 | K18: =IF(ISNUMBER($E$11),prep_table!$C$46,prep_table!$C$69) -> 0 | L18: =IF(ISNUMBER($E$11),prep_table!$C$47,prep_table!$C$77) -> 0 | M18: =IF(ISNUMBER($E$11),prep_table!$C$48,prep_table!$C$85) -> 0 | N18: =IF(ISNUMBER($E$11),prep_table!$C$49,prep_table!$C$93) -> 0
B19: E | C19: =IF(ISNUMBER($E$11),prep_table!$C$50,prep_table!$C$6) -> 0 | D19: =IF(ISNUMBER($E$11),prep_table!$C$51,prep_table!$C$14) -> 0 | E19: =IF(ISNUMBER($E$11),prep_table!$C$52,prep_table!$C$22) -> 0 | F19: =IF(ISNUMBER($E$11),prep_table!$C$53,prep_table!$C$30) -> 0 | G19: =IF(ISNUMBER($E$11),prep_table!$C$54,prep_table!$C$38) -> 0 | H19: =IF(ISNUMBER($E$11),prep_table!$C$55,prep_table!$C$46) -> 0 | I19: =IF(ISNUMBER($E$11),prep_table!$C$56,prep_table!$C$54) -> 0 | J19: =IF(ISNUMBER($E$11),prep_table!$C$57,prep_table!$C$62) -> 0 | K19: =IF(ISNUMBER($E$11),prep_table!$C$58,prep_table!$C$70) -> 0 | L19: =IF(ISNUMBER($E$11),prep_table!$C$59,prep_table!$C$78) -> 0 | M19: =IF(ISNUMBER($E$11),prep_table!$C$60,prep_table!$C$86) -> 0 | N19: =IF(ISNUMBER($E$11),prep_table!$C$61,prep_table!$C$94) -> 0
B20: F | C20: =IF(ISNUMBER($E$11),prep_table!$C$62,prep_table!$C$7) -> 0 | D20: =IF(ISNUMBER($E$11),prep_table!$C$63,prep_table!$C$15) -> 0 | E20: =IF(ISNUMBER($E$11),prep_table!$C$64,prep_table!$C$23) -> 0 | F20: =IF(ISNUMBER($E$11),prep_table!$C$65,prep_table!$C$31) -> 0 | G20: =IF(ISNUMBER($E$11),prep_table!$C$66,prep_table!$C$39) -> 0 | H20: =IF(ISNUMBER($E$11),prep_table!$C$67,prep_table!$C$47) -> 0 | I20: =IF(ISNUMBER($E$11),prep_table!$C$68,prep_table!$C$55) -> 0 | J20: =IF(ISNUMBER($E$11),prep_table!$C$69,prep_table!$C$63) -> 0 | K20: =IF(ISNUMBER($E$11),prep_table!$C$70,prep_table!$C$71) -> 0 | L20: =IF(ISNUMBER($E$11),prep_table!$C$71,prep_table!$C$79) -> 0 | M20: =IF(ISNUMBER($E$11),prep_table!$C$72,prep_table!$C$87) -> 0 | N20: =IF(ISNUMBER($E$11),prep_table!$C$73,prep_table!$C$95) -> 0
B21: G | C21: =IF(ISNUMBER($E$11),prep_table!$C$74,prep_table!$C$8) -> 0 | D21: =IF(ISNUMBER($E$11),prep_table!$C$75,prep_table!$C$16) -> 0 | E21: =IF(ISNUMBER($E$11),prep_table!$C$76,prep_table!$C$24) -> 0 | F21: =IF(ISNUMBER($E$11),prep_table!$C$77,prep_table!$C$32) -> 0 | G21: =IF(ISNUMBER($E$11),prep_table!$C$78,prep_table!$C$40) -> 0 | H21: =IF(ISNUMBER($E$11),prep_table!$C$79,prep_table!$C$48) -> 0 | I21: =IF(ISNUMBER($E$11),prep_table!$C$80,prep_table!$C$56) -> 0 | J21: =IF(ISNUMBER($E$11),prep_table!$C$81,prep_table!$C$64) -> 0 | K21: =IF(ISNUMBER($E$11),prep_table!$C$82,prep_table!$C$72) -> 0 | L21: =IF(ISNUMBER($E$11),prep_table!$C$83,prep_table!$C$80) -> 0 | M21: =IF(ISNUMBER($E$11),prep_table!$C$84,prep_table!$C$88) -> 0 | N21: =IF(ISNUMBER($E$11),prep_table!$C$85,prep_table!$C$96) -> 0
B22: H | C22: =IF(ISNUMBER($E$11),prep_table!$C$86,prep_table!$C$9) -> 0 | D22: =IF(ISNUMBER($E$11),prep_table!$C$87,prep_table!$C$17) -> 0 | E22: =IF(ISNUMBER($E$11),prep_table!$C$88,prep_table!$C$25) -> 0 | F22: =IF(ISNUMBER($E$11),prep_table!$C$89,prep_table!$C$33) -> 0 | G22: =IF(ISNUMBER($E$11),prep_table!$C$90,prep_table!$C$41) -> 0 | H22: =IF(ISNUMBER($E$11),prep_table!$C$91,prep_table!$C$49) -> 0 | I22: =IF(ISNUMBER($E$11),prep_table!$C$92,prep_table!$C$57) -> 0 | J22: =IF(ISNUMBER($E$11),prep_table!$C$93,prep_table!$C$65) -> 0 | K22: =IF(ISNUMBER($E$11),prep_table!$C$94,prep_table!$C$73) -> 0 | L22: =IF(ISNUMBER($E$11),prep_table!$C$95,prep_table!$C$81) -> 0 | M22: =IF(ISNUMBER($E$11),prep_table!$C$96,prep_table!$C$89) -> 0 | N22: =IF(ISNUMBER($E$11),prep_table!$C$97,prep_table!$C$97) -> 0
A23: µL RNA: | C23: 1 | D23: 2 | E23: 3 | F23: 4 | G23: 5 | H23: 6 | I23: 7 | J23: 8 | K23: 9 | L23: 10 | M23: 11 | N23: 12
B24: A | C24: =IF(ISNUMBER($E$11),prep_table!$O$2,prep_table!$O$2) -> 5 | D24: =IF(ISNUMBER($E$11),prep_table!$O$3,prep_table!$O$10) -> 5 | E24: =IF(ISNUMBER($E$11),prep_table!$O$4,prep_table!$O$18) -> 5 | F24: =IF(ISNUMBER($E$11),prep_table!$O$5,prep_table!$O$26) -> 5 | G24: =IF(ISNUMBER($E$11),prep_table!$O$6,prep_table!$O$34) -> 5 | H24: =IF(ISNUMBER($E$11),prep_table!$O$7,prep_table!$O$42) -> 5 | I24: =IF(ISNUMBER($E$11),prep_table!$O$8,prep_table!$O$50) -> 5 | J24: =IF(ISNUMBER($E$11),prep_table!$O$9,prep_table!$O$58) -> 5 | K24: =IF(ISNUMBER($E$11),prep_table!$O$10,prep_table!$O$66) -> 5 | L24: =IF(ISNUMBER($E$11),prep_table!$O$11,prep_table!$O$74) -> 5 | M24: =IF(ISNUMBER($E$11),prep_table!$O$12,prep_table!$O$82) -> 5 | N24: =IF(ISNUMBER($E$11),prep_table!$O$13,prep_table!$O$90) -> 5
B25: B | C25: =IF(ISNUMBER($E$11),prep_table!$O$14,prep_table!$O$3) -> 5 | D25: =IF(ISNUMBER($E$11),prep_table!$O$15,prep_table!$O$11) -> 5 | E25: =IF(ISNUMBER($E$11),prep_table!$O$16,prep_table!$O$19) -> 5 | F25: =IF(ISNUMBER($E$11),prep_table!$O$17,prep_table!$O$27) -> 5 | G25: =IF(ISNUMBER($E$11),prep_table!$O$18,prep_table!$O$35) -> 5 | H25: =IF(ISNUMBER($E$11),prep_table!$O$19,prep_table!$O$43) -> 5 | I25: =IF(ISNUMBER($E$11),prep_table!$O$20,prep_table!$O$51) -> 5 | J25: =IF(ISNUMBER($E$11),prep_table!$O$21,prep_table!$O$59) -> 5 | K25: =IF(ISNUMBER($E$11),prep_table!$O$22,prep_table!$O$67) -> 5 | L25: =IF(ISNUMBER($E$11),prep_table!$O$23,prep_table!$O$75) -> 5 | M25: =IF(ISNUMBER($E$11),prep_table!$O$24,prep_table!$O$83) -> 5 | N25: =IF(ISNUMBER($E$11),prep_table!$O$25,prep_table!$O$91) -> 5
B26: C | C26: =IF(ISNUMBER($E$11),prep_table!$O$26,prep_table!$O$4) -> 5 | D26: =IF(ISNUMBER($E$11),prep_table!$O$27,prep_table!$O$12) -> 5 | E26: =IF(ISNUMBER($E$11),prep_table!$O$28,prep_table!$O$20) -> 5 | F26: =IF(ISNUMBER($E$11),prep_table!$O$29,prep_table!$O$28) -> 5 | G26: =IF(ISNUMBER($E$11),prep_table!$O$30,prep_table!$O$36) -> 5 | H26: =IF(ISNUMBER($E$11),prep_table!$O$31,prep_table!$O$44) -> 5 | I26: =IF(ISNUMBER($E$11),prep_table!$O$32,prep_table!$O$52) -> 5 | J26: =IF(ISNUMBER($E$11),prep_table!$O$33,prep_table!$O$60) -> 5 | K26: =IF(ISNUMBER($E$11),prep_table!$O$34,prep_table!$O$68) -> 5 | L26: =IF(ISNUMBER($E$11),prep_table!$O$35,prep_table!$O$76) -> 5 | M26: =IF(ISNUMBER($E$11),prep_table!$O$36,prep_table!$O$84) -> 5 | N26: =IF(ISNUMBER($E$11),prep_table!$O$37,prep_table!$O$92) -> 5
B27: D | C27: =IF(ISNUMBER($E$11),prep_table!$O$38,prep_table!$O$5) -> 5 | D27: =IF(ISNUMBER($E$11),prep_table!$O$39,prep_table!$O$13) -> 5 | E27: =IF(ISNUMBER($E$11),prep_table!$O$40,prep_table!$O$21) -> 5 | F27: =IF(ISNUMBER($E$11),prep_table!$O$41,prep_table!$O$29) -> 5 | G27: =IF(ISNUMBER($E$11),prep_table!$O$42,prep_table!$O$37) -> 5 | H27: =IF(ISNUMBER($E$11),prep_table!$O$43,prep_table!$O$45) -> 5 | I27: =IF(ISNUMBER($E$11),prep_table!$O$44,prep_table!$O$53) -> 5 | J27: =IF(ISNUMBER($E$11),prep_table!$O$45,prep_table!$O$61) -> 5 | K27: =IF(ISNUMBER($E$11),prep_table!$O$46,prep_table!$O$69) -> 5 | L27: =IF(ISNUMBER($E$11),prep_table!$O$47,prep_table!$O$77) -> 5 | M27: =IF(ISNUMBER($E$11),prep_table!$O$48,prep_table!$O$85) -> 5 | N27: =IF(ISNUMBER($E$11),prep_table!$O$49,prep_table!$O$93) -> 5
B28: E | C28: =IF(ISNUMBER($E$11),prep_table!$O$50,prep_table!$O$6) -> 5 | D28: =IF(ISNUMBER($E$11),prep_table!$O$51,prep_table!$O$14) -> 5 | E28: =IF(ISNUMBER($E$11),prep_table!$O$52,prep_table!$O$22) -> 5 | F28: =IF(ISNUMBER($E$11),prep_table!$O$53,prep_table!$O$30) -> 5 | G28: =IF(ISNUMBER($E$11),prep_table!$O$54,prep_table!$O$38) -> 5 | H28: =IF(ISNUMBER($E$11),prep_table!$O$55,prep_table!$O$46) -> 5 | I28: =IF(ISNUMBER($E$11),prep_table!$O$56,prep_table!$O$54) -> 5 | J28: =IF(ISNUMBER($E$11),prep_table!$O$57,prep_table!$O$62) -> 5 | K28: =IF(ISNUMBER($E$11),prep_table!$O$58,prep_table!$O$70) -> 5 | L28: =IF(ISNUMBER($E$11),prep_table!$O$59,prep_table!$O$78) -> 5 | M28: =IF(ISNUMBER($E$11),prep_table!$O$60,prep_table!$O$86) -> 5 | N28: =IF(ISNUMBER($E$11),prep_table!$O$61,prep_table!$O$94) -> 5
B29: F | C29: =IF(ISNUMBER($E$11),prep_table!$O$62,prep_table!$O$7) -> 5 | D29: =IF(ISNUMBER($E$11),prep_table!$O$63,prep_table!$O$15) -> 5 | E29: =IF(ISNUMBER($E$11),prep_table!$O$64,prep_table!$O$23) -> 5 | F29: =IF(ISNUMBER($E$11),prep_table!$O$65,prep_table!$O$31) -> 5 | G29: =IF(ISNUMBER($E$11),prep_table!$O$66,prep_table!$O$39) -> 5 | H29: =IF(ISNUMBER($E$11),prep_table!$O$67,prep_table!$O$47) -> 5 | I29: =IF(ISNUMBER($E$11),prep_table!$O$68,prep_table!$O$55) -> 5 | J29: =IF(ISNUMBER($E$11),prep_table!$O$69,prep_table!$O$63) -> 5 | K29: =IF(ISNUMBER($E$11),prep_table!$O$70,prep_table!$O$71) -> 5 | L29: =IF(ISNUMBER($E$11),prep_table!$O$71,prep_table!$O$79) -> 5 | M29: =IF(ISNUMBER($E$11),prep_table!$O$72,prep_table!$O$87) -> 5 | N29: =IF(ISNUMBER($E$11),prep_table!$O$73,prep_table!$O$95) -> 5
B30: G | C30: =IF(ISNUMBER($E$11),prep_table!$O$74,prep_table!$O$8) -> 5 | D30: =IF(ISNUMBER($E$11),prep_table!$O$75,prep_table!$O$16) -> 5 | E30: =IF(ISNUMBER($E$11),prep_table!$O$76,prep_table!$O$24) -> 5 | F30: =IF(ISNUMBER($E$11),prep_table!$O$77,prep_table!$O$32) -> 5 | G30: =IF(ISNUMBER($E$11),prep_table!$O$78,prep_table!$O$40) -> 5 | H30: =IF(ISNUMBER($E$11),prep_table!$O$79,prep_table!$O$48) -> 5 | I30: =IF(ISNUMBER($E$11),prep_table!$O$80,prep_table!$O$56) -> 5 | J30: =IF(ISNUMBER($E$11),prep_table!$O$81,prep_table!$O$64) -> 5 | K30: =IF(ISNUMBER($E$11),prep_table!$O$82,prep_table!$O$72) -> 5 | L30: =IF(ISNUMBER($E$11),prep_table!$O$83,prep_table!$O$80) -> 5 | M30: =IF(ISNUMBER($E$11),prep_table!$O$84,prep_table!$O$88) -> 5 | N30: =IF(ISNUMBER($E$11),prep_table!$O$85,prep_table!$O$96) -> 5
B31: H | C31: =IF(ISNUMBER($E$11),prep_table!$O$86,prep_table!$O$9) -> 5 | D31: =IF(ISNUMBER($E$11),prep_table!$O$87,prep_table!$O$17) -> 5 | E31: =IF(ISNUMBER($E$11),prep_table!$O$88,prep_table!$O$25) -> 5 | F31: =IF(ISNUMBER($E$11),prep_table!$O$89,prep_table!$O$33) -> 5 | G31: =IF(ISNUMBER($E$11),prep_table!$O$90,prep_table!$O$41) -> 5 | H31: =IF(ISNUMBER($E$11),prep_table!$O$91,prep_table!$O$49) -> 5 | I31: =IF(ISNUMBER($E$11),prep_table!$O$92,prep_table!$O$57) -> 5 | J31: =IF(ISNUMBER($E$11),prep_table!$O$93,prep_table!$O$65) -> 5 | K31: =IF(ISNUMBER($E$11),prep_table!$O$94,prep_table!$O$73) -> 5 | L31: =IF(ISNUMBER($E$11),prep_table!$O$95,prep_table!$O$81) -> 5 | M31: =IF(ISNUMBER($E$11),prep_table!$O$96,prep_table!$O$89) -> 5 | N31: =IF(ISNUMBER($E$11),prep_table!$O$97,prep_table!$O$97) -> 5
A32: µL water: | C32: 1 | D32: 2 | E32: 3 | F32: 4 | G32: 5 | H32: 6 | I32: 7 | J32: 8 | K32: 9 | L32: 10 | M32: 11 | N32: 12
B33: A | C33: =IF(ISNUMBER($E$11),prep_table!$N$2,prep_table!$N$2) -> 0 | D33: =IF(ISNUMBER($E$11),prep_table!$N$3,prep_table!$N$10) -> 0 | E33: =IF(ISNUMBER($E$11),prep_table!$N$4,prep_table!$N$18) -> 0 | F33: =IF(ISNUMBER($E$11),prep_table!$N$5,prep_table!$N$26) -> 0 | G33: =IF(ISNUMBER($E$11),prep_table!$N$6,prep_table!$N$34) -> 0 | H33: =IF(ISNUMBER($E$11),prep_table!$N$7,prep_table!$N$42) -> 0 | I33: =IF(ISNUMBER($E$11),prep_table!$N$8,prep_table!$N$50) -> 0 | J33: =IF(ISNUMBER($E$11),prep_table!$N$9,prep_table!$N$58) -> 0 | K33: =IF(ISNUMBER($E$11),prep_table!$N$10,prep_table!$N$66) -> 0 | L33: =IF(ISNUMBER($E$11),prep_table!$N$11,prep_table!$N$74) -> 0 | M33: =IF(ISNUMBER($E$11),prep_table!$N$12,prep_table!$N$82) -> 0 | N33: =IF(ISNUMBER($E$11),prep_table!$N$13,prep_table!$N$90) -> 0
B34: B | C34: =IF(ISNUMBER($E$11),prep_table!$N$14,prep_table!$N$3) -> 0 | D34: =IF(ISNUMBER($E$11),prep_table!$N$15,prep_table!$N$11) -> 0 | E34: =IF(ISNUMBER($E$11),prep_table!$N$16,prep_table!$N$19) -> 0 | F34: =IF(ISNUMBER($E$11),prep_table!$N$17,prep_table!$N$27) -> 0 | G34: =IF(ISNUMBER($E$11),prep_table!$N$18,prep_table!$N$35) -> 0 | H34: =IF(ISNUMBER($E$11),prep_table!$N$19,prep_table!$N$43) -> 0 | I34: =IF(ISNUMBER($E$11),prep_table!$N$20,prep_table!$N$51) -> 0 | J34: =IF(ISNUMBER($E$11),prep_table!$N$21,prep_table!$N$59) -> 0 | K34: =IF(ISNUMBER($E$11),prep_table!$N$22,prep_table!$N$67) -> 0 | L34: =IF(ISNUMBER($E$11),prep_table!$N$23,prep_table!$N$75) -> 0 | M34: =IF(ISNUMBER($E$11),prep_table!$N$24,prep_table!$N$83) -> 0 | N34: =IF(ISNUMBER($E$11),prep_table!$N$25,prep_table!$N$91) -> 0
B35: C | C35: =IF(ISNUMBER($E$11),prep_table!$N$26,prep_table!$N$4) -> 0 | D35: =IF(ISNUMBER($E$11),prep_table!$N$27,prep_table!$N$12) -> 0 | E35: =IF(ISNUMBER($E$11),prep_table!$N$28,prep_table!$N$20) -> 0 | F35: =IF(ISNUMBER($E$11),prep_table!$N$29,prep_table!$N$28) -> 0 | G35: =IF(ISNUMBER($E$11),prep_table!$N$30,prep_table!$N$36) -> 0 | H35: =IF(ISNUMBER($E$11),prep_table!$N$31,prep_table!$N$44) -> 0 | I35: =IF(ISNUMBER($E$11),prep_table!$N$32,prep_table!$N$52) -> 0 | J35: =IF(ISNUMBER($E$11),prep_table!$N$33,prep_table!$N$60) -> 0 | K35: =IF(ISNUMBER($E$11),prep_table!$N$34,prep_table!$N$68) -> 0 | L35: =IF(ISNUMBER($E$11),prep_table!$N$35,prep_table!$N$76) -> 0 | M35: =IF(ISNUMBER($E$11),prep_table!$N$36,prep_table!$N$84) -> 0 | N35: =IF(ISNUMBER($E$11),prep_table!$N$37,prep_table!$N$92) -> 0
B36: D | C36: =IF(ISNUMBER($E$11),prep_table!$N$38,prep_table!$N$5) -> 0 | D36: =IF(ISNUMBER($E$11),prep_table!$N$39,prep_table!$N$13) -> 0 | E36: =IF(ISNUMBER($E$11),prep_table!$N$40,prep_table!$N$21) -> 0 | F36: =IF(ISNUMBER($E$11),prep_table!$N$41,prep_table!$N$29) -> 0 | G36: =IF(ISNUMBER($E$11),prep_table!$N$42,prep_table!$N$37) -> 0 | H36: =IF(ISNUMBER($E$11),prep_table!$N$43,prep_table!$N$45) -> 0 | I36: =IF(ISNUMBER($E$11),prep_table!$N$44,prep_table!$N$53) -> 0 | J36: =IF(ISNUMBER($E$11),prep_table!$N$45,prep_table!$N$61) -> 0 | K36: =IF(ISNUMBER($E$11),prep_table!$N$46,prep_table!$N$69) -> 0 | L36: =IF(ISNUMBER($E$11),prep_table!$N$47,prep_table!$N$77) -> 0 | M36: =IF(ISNUMBER($E$11),prep_table!$N$48,prep_table!$N$85) -> 0 | N36: =IF(ISNUMBER($E$11),prep_table!$N$49,prep_table!$N$93) -> 0
B37: E | C37: =IF(ISNUMBER($E$11),prep_table!$N$50,prep_table!$N$6) -> 0 | D37: =IF(ISNUMBER($E$11),prep_table!$N$51,prep_table!$N$14) -> 0 | E37: =IF(ISNUMBER($E$11),prep_table!$N$52,prep_table!$N$22) -> 0 | F37: =IF(ISNUMBER($E$11),prep_table!$N$53,prep_table!$N$30) -> 0 | G37: =IF(ISNUMBER($E$11),prep_table!$N$54,prep_table!$N$38) -> 0 | H37: =IF(ISNUMBER($E$11),prep_table!$N$55,prep_table!$N$46) -> 0 | I37: =IF(ISNUMBER($E$11),prep_table!$N$56,prep_table!$N$54) -> 0 | J37: =IF(ISNUMBER($E$11),prep_table!$N$57,prep_table!$N$62) -> 0 | K37: =IF(ISNUMBER($E$11),prep_table!$N$58,prep_table!$N$70) -> 0 | L37: =IF(ISNUMBER($E$11),prep_table!$N$59,prep_table!$N$78) -> 0 | M37: =IF(ISNUMBER($E$11),prep_table!$N$60,prep_table!$N$86) -> 0 | N37: =IF(ISNUMBER($E$11),prep_table!$N$61,prep_table!$N$94) -> 0
B38: F | C38: =IF(ISNUMBER($E$11),prep_table!$N$62,prep_table!$N$7) -> 0 | D38: =IF(ISNUMBER($E$11),prep_table!$N$63,prep_table!$N$15) -> 0 | E38: =IF(ISNUMBER($E$11),prep_table!$N$64,prep_table!$N$23) -> 0 | F38: =IF(ISNUMBER($E$11),prep_table!$N$65,prep_table!$N$31) -> 0 | G38: =IF(ISNUMBER($E$11),prep_table!$N$66,prep_table!$N$39) -> 0 | H38: =IF(ISNUMBER($E$11),prep_table!$N$67,prep_table!$N$47) -> 0 | I38: =IF(ISNUMBER($E$11),prep_table!$N$68,prep_table!$N$55) -> 0 | J38: =IF(ISNUMBER($E$11),prep_table!$N$69,prep_table!$N$63) -> 0 | K38: =IF(ISNUMBER($E$11),prep_table!$N$70,prep_table!$N$71) -> 0 | L38: =IF(ISNUMBER($E$11),prep_table!$N$71,prep_table!$N$79) -> 0 | M38: =IF(ISNUMBER($E$11),prep_table!$N$72,prep_table!$N$87) -> 0 | N38: =IF(ISNUMBER($E$11),prep_table!$N$73,prep_table!$N$95) -> 0
B39: G | C39: =IF(ISNUMBER($E$11),prep_table!$N$74,prep_table!$N$8) -> 0 | D39: =IF(ISNUMBER($E$11),prep_table!$N$75,prep_table!$N$16) -> 0 | E39: =IF(ISNUMBER($E$11),prep_table!$N$76,prep_table!$N$24) -> 0 | F39: =IF(ISNUMBER($E$11),prep_table!$N$77,prep_table!$N$32) -> 0 | G39: =IF(ISNUMBER($E$11),prep_table!$N$78,prep_table!$N$40) -> 0 | H39: =IF(ISNUMBER($E$11),prep_table!$N$79,prep_table!$N$48) -> 0 | I39: =IF(ISNUMBER($E$11),prep_table!$N$80,prep_table!$N$56) -> 0 | J39: =IF(ISNUMBER($E$11),prep_table!$N$81,prep_table!$N$64) -> 0 | K39: =IF(ISNUMBER($E$11),prep_table!$N$82,prep_table!$N$72) -> 0 | L39: =IF(ISNUMBER($E$11),prep_table!$N$83,prep_table!$N$80) -> 0 | M39: =IF(ISNUMBER($E$11),prep_table!$N$84,prep_table!$N$88) -> 0 | N39: =IF(ISNUMBER($E$11),prep_table!$N$85,prep_table!$N$96) -> 0
B40: H | C40: =IF(ISNUMBER($E$11),prep_table!$N$86,prep_table!$N$9) -> 0 | D40: =IF(ISNUMBER($E$11),prep_table!$N$87,prep_table!$N$17) -> 0 | E40: =IF(ISNUMBER($E$11),prep_table!$N$88,prep_table!$N$25) -> 0 | F40: =IF(ISNUMBER($E$11),prep_table!$N$89,prep_table!$N$33) -> 0 | G40: =IF(ISNUMBER($E$11),prep_table!$N$90,prep_table!$N$41) -> 0 | H40: =IF(ISNUMBER($E$11),prep_table!$N$91,prep_table!$N$49) -> 0 | I40: =IF(ISNUMBER($E$11),prep_table!$N$92,prep_table!$N$57) -> 0 | J40: =IF(ISNUMBER($E$11),prep_table!$N$93,prep_table!$N$65) -> 0 | K40: =IF(ISNUMBER($E$11),prep_table!$N$94,prep_table!$N$73) -> 0 | L40: =IF(ISNUMBER($E$11),prep_table!$N$95,prep_table!$N$81) -> 0 | M40: =IF(ISNUMBER($E$11),prep_table!$N$96,prep_table!$N$89) -> 0 | N40: =IF(ISNUMBER($E$11),prep_table!$N$97,prep_table!$N$97) -> 0
...
