Workbook
Name _Hlk114062637: '3'' GEMX'!$C$120
Name _Hlk114062637: '3''_OCM_4plex'!$C$114
Name _Hlk114062637: '5''_GEMX'!$C$216
Name _Hlk114062637: '5''_OCM_4plex'!$C$208
Name _Hlk114062637: Flex_GEMX_v2!$C$199

Sheet prep_table
A1: sample_num | B1: plate_well | C1: library_name | D1: library_id | E1: requestor | F1: pool | G1: library_kits | H1: library_prep_type | I1: comment | J1: cDNA_conc_ng_ul | K1: cDNA_input_ul | L1: cDNA_input_ng | M1: index_pcr_cycles | N1: index_well | O1: kit_i7 | P1: kit_i5 | Q1: sequence_i7 | R1: name_i7 | S1: sequence_i5 | T1: name_i5 | U1: lib_conc_ng_ul | V1: ba | W1: pooling_factor | X1: ul_pooling
A2: 1 | L2: =J2*K2 -> 0 | W2: =+MAX($U$2:$U$97)/U2 -> #DIV/0! | X2: =+W2*1 -> #DIV/0!
A3: 2 | L3: =J3*K3 -> 0 | W3: =+MAX($U$2:$U$97)/U3 -> #DIV/0! | X3: =+W3*1 -> #DIV/0!
A4: 3 | L4: =J4*K4 -> 0 | W4: =+MAX($U$2:$U$97)/U4 -> #DIV/0! | X4: =+W4*1 -> #DIV/0!
A5: 4 | L5: =J5*K5 -> 0 | W5: =+MAX($U$2:$U$97)/U5 -> #DIV/0! | X5: =+W5*1 -> #DIV/0!
A6: 5 | L6: =J6*K6 -> 0 | W6: =+MAX($U$2:$U$97)/U6 -> #DIV/0! | X6: =+W6*1 -> #DIV/0!
A7: 6 | L7: =J7*K7 -> 0 | W7: =+MAX($U$2:$U$97)/U7 -> #DIV/0! | X7: =+W7*1 -> #DIV/0!
A8: 7 | L8: =J8*K8 -> 0 | W8: =+MAX($U$2:$U$97)/U8 -> #DIV/0! | X8: =+W8*1 -> #DIV/0!
A9: 8 | L9: =J9*K9 -> 0 | W9: =+MAX($U$2:$U$97)/U9 -> #DIV/0! | X9: =+W9*1 -> #DIV/0!
A10: 9 | L10: =J10*K10 -> 0 | W10: =+MAX($U$2:$U$97)/U10 -> #DIV/0! | X10: =+W10*1 -> #DIV/0!
A11: 10 | L11: =J11*K11 -> 0 | W11: =+MAX($U$2:$U$97)/U11 -> #DIV/0! | X11: =+W11*1 -> #DIV/0!
A12: 11 | L12: =J12*K12 -> 0 | W12: =+MAX($U$2:$U$97)/U12 -> #DIV/0! | X12: =+W12*1 -> #DIV/0!
A13: 12 | L13: =J13*K13 -> 0 | W13: =+MAX($U$2:$U$97)/U13 -> #DIV/0! | X13: =+W13*1 -> #DIV/0!
... A97: 96 | L97: =J97*K97 -> 0 | W97: =+MAX($U$2:$U$97)/U97 -> #DIV/0! | X97: =+W97*1 -> #DIV/0!

Sheet 10X_table
A1: sample_num | B1: sample_name | C1: library_name | D1: library_id | E1: requestor | F1: library_prep_type | G1: cellcount_permL | H1: cellcount_peruL | I1: volume_ul | J1: Targeted_cell_loaded_default_16500 | K1: ul_sample | L1: ul_water | M1: Chip_problems
A2: 1 | C2: =prep_table!C2 -> 0 | D2: =prep_table!D2 -> 0 | E2: =prep_table!E2 -> 0 | H2: =G2*10^3 -> 0 | M2: =Equal_Pooling_RevB!H15
A3: 2 | C3: =prep_table!C3 -> 0 | D3: =prep_table!D3 -> 0 | E3: =prep_table!E3 -> 0 | H3: =G3*10^3 -> 0 | M3: =Equal_Pooling_RevB!H16
A4: 3 | C4: =prep_table!C4 -> 0 | D4: =prep_table!D4 -> 0 | E4: =prep_table!E4 -> 0 | H4: =G4*10^3 -> 0 | M4: =Equal_Pooling_RevB!H17
A5: 4 | C5: =prep_table!C5 -> 0 | D5: =prep_table!D5 -> 0 | E5: =prep_table!E5 -> 0 | H5: =G5*10^3 -> 0 | M5: =Equal_Pooling_RevB!H18
A6: 5 | C6: =prep_table!C6 -> 0 | D6: =prep_table!D6 -> 0 | E6: =prep_table!E6 -> 0 | H6: =G6*10^3 -> 0 | M6: =Equal_Pooling_RevB!H19
A7: 6 | C7: =prep_table!C7 -> 0 | D7: =prep_table!D7 -> 0 | E7: =prep_table!E7 -> 0 | H7: =G7*10^3 -> 0 | M7: =Equal_Pooling_RevB!H20
A8: 7 | C8: =prep_table!C8 -> 0 | D8: =prep_table!D8 -> 0 | E8: =prep_table!E8 -> 0 | H8: =G8*10^3 -> 0 | M8: =Equal_Pooling_RevB!H21
A9: 8 | C9: =prep_table!C9 -> 0 | D9: =prep_table!D9 -> 0 | E9: =prep_table!E9 -> 0 | H9: =G9*10^3 -> 0 | M9: =Equal_Pooling_RevB!H22
A10: 9 | C10: =prep_table!C10 -> 0 | D10: =prep_table!D10 -> 0 | E10: =prep_table!E10 -> 0 | H10: =G10*10^3 -> 0 | M10: =Equal_Pooling_RevB!H23
A11: 10 | C11: =prep_table!C11 -> 0 | D11: =prep_table!D11 -> 0 | E11: =prep_table!E11 -> 0 | H11: =G11*10^3 -> 0 | M11: =Equal_Pooling_RevB!H24
A12: 11 | C12: =prep_table!C12 -> 0 | D12: =prep_table!D12 -> 0 | E12: =prep_table!E12 -> 0 | H12: =G12*10^3 -> 0 | M12: =Equal_Pooling_RevB!H25
A13: 12 | C13: =prep_table!C13 -> 0 | D13: =prep_table!D13 -> 0 | E13: =prep_table!E13 -> 0 | H13: =G13*10^3 -> 0 | M13: =Equal_Pooling_RevB!H26
... A17: 16 | C17: =prep_table!C17 -> 0 | D17: =prep_table!D17 -> 0 | E17: =prep_table!E17 -> 0 | H17: =G17*10^3 -> 0 | M17: =Equal_Pooling_RevB!H30

Sheet FLEX_table
A1: sample_num | B1: sample_name | C1: cellcount_permL | D1: cellcount_peruL | E1: targeted_cellinput | F1: vol_used_for_hybridization | G1: Probe Barcode Well | H1: cellcount_after_hyb | I1: sample_volume_pooling | J1: Chip_problems
A2: 1 | D2: =C2/10^3 -> 0 | F2: =E2/D2 -> #DIV/0! | I2: =Equal_Pooling_RevB!H15 | J2: =Equal_Pooling_RevB!I15
A3: 2 | D3: =C3/10^3 -> 0 | F3: =E3/D3 -> #DIV/0! | I3: =Equal_Pooling_RevB!H16 | J3: =Equal_Pooling_RevB!I16
A4: 3 | D4: =C4/10^3 -> 0 | F4: =E4/D4 -> #DIV/0! | I4: =Equal_Pooling_RevB!H17 | J4: =Equal_Pooling_RevB!I17
A5: 4 | D5: =C5/10^3 -> 0 | F5: =E5/D5 -> #DIV/0! | I5: =Equal_Pooling_RevB!H18 | J5: =Equal_Pooling_RevB!I18
A6: 5 | D6: =C6/10^3 -> 0 | F6: =E6/D6 -> #DIV/0! | I6: =Equal_Pooling_RevB!H19 | J6: =Equal_Pooling_RevB!I19
A7: 6 | D7: =C7/10^3 -> 0 | F7: =E7/D7 -> #DIV/0! | I7: =Equal_Pooling_RevB!H20 | J7: =Equal_Pooling_RevB!I20
A8: 7 | D8: =C8/10^3 -> 0 | F8: =E8/D8 -> #DIV/0! | I8: =Equal_Pooling_RevB!H21 | J8: =Equal_Pooling_RevB!I21
A9: 8 | D9: =C9/10^3 -> 0 | F9: =E9/D9 -> #DIV/0! | I9: =Equal_Pooling_RevB!H22 | J9: =Equal_Pooling_RevB!I22
A10: 9 | D10: =C10/10^3 -> 0 | F10: =E10/D10 -> #DIV/0! | I10: =Equal_Pooling_RevB!H23 | J10: =Equal_Pooling_RevB!I23
A11: 10 | D11: =C11/10^3 -> 0 | F11: =E11/D11 -> #DIV/0! | I11: =Equal_Pooling_RevB!H24 | J11: =Equal_Pooling_RevB!I24
A12: 11 | D12: =C12/10^3 -> 0 | F12: =E12/D12 -> #DIV/0! | I12: =Equal_Pooling_RevB!H25 | J12: =Equal_Pooling_RevB!I25
A13: 12 | D13: =C13/10^3 -> 0 | F13: =E13/D13 -> #DIV/0! | I13: =Equal_Pooling_RevB!H26 | J13: =Equal_Pooling_RevB!I26
... A17: 16 | D17: =C17/10^3 -> 0 | F17: =E17/D17 -> #DIV/0! | I17: =Equal_Pooling_RevB!H30 | J17: =Equal_Pooling_RevB!I30

Sheet 3' GEMX
C1: Checklist 10X Chromium GEM-X Single Cell 3' Reagent Kits v4 Library Preparation
A2: Library prep number:
A3: SOP Version: | K3: Indexplate A: | L3: TT Set A
A4: Single Cell 3’ GEM Kit v4 LOT#: | J4: Signature:
A5: Single Cell 3’ Gel Bead Kitv4 LOT#:
A6: Chip GEMX 3' Kit LOT# | I6: TT Set A Kit LOT#
A7: Library Construction Kit C LOT#:
A8: Library person:
A9: Library date:
A10: Comments:
A11: Number of samples:
B12: GEM Generation & Barcoding
B13: Equilibrate Gel Bead, RT Reagent E, TSO B, Reducing Agent B to RT for 30 min
B14: Prepare the following MM and pipet 28.4 µL in each tube on ice
E15: Volume per reaction | F15: =CONCATENATE(" Volume for ",$E$11," samples") -> Volume for samples
B16: Mix: | D16: RT Reagent E | E16: 16.3 | F16: =E16*$E$11*1.1 -> 0 | G16: µL
D17: Template Switch Oligo B | E17: 3.1 | F17: =E17*$E$11*1.1 -> 0 | G17: µL
D18: Reducing Agent B | E18: 2 | F18: =E18*$E$11*1.1 -> 0 | G18: µL
D19: RT Enzyme E | E19: 7 | F19: =E19*$E$11*1.1 -> 0 | G19: µL
E20: =SUM(E16:E19) -> 28.4 | F20: =SUM(F16:F19) -> 0 | G20: µL | H20: mix, spin
B21: Assemble the GEM-X 3' Chip and pipet glycerol in the unused wells: 60 µL into ROW 1, 60 µL into ROW 2, 250 µL into ROW 3
B22: Vortex beads for 30 sec, centrifuge for 5 sec
B23: Add 1x PBS into the MM for each sample and mix
D24: Sample name | E24: cell count/mL | F24: V 1X PBS [µL] | G24: V Sample [µL] | J24: normally we target 29000 cells for 3' GEM-X
C25: 1
C26: 2
C27: 3
C28: 4
C29: 5
C30: 6
C31: 7
C32: 8
B33: Pipet 60 µl of the Master Mix + Cell suspension into the chip in row 1
B34: Reverse pipet 60 µl of beads into row 2 and wait for 30s.
B35: Pipet 250 µl of partitioning oil in row 3
B36: Close lid and put it into chromium
B37: Transfer gems slowly into tubes with cap put it into thermocycler and Incubate: | I37: 48°C/45 min | K37: lid = 48°C, volume 125 µL
I38: 85°C/5 min -> hold 4°C
B39: Post GEM-RT Cleanup & cDNA Amplification
B40: Add 125 µL of Recovery Agent to each sample, wait for 2 min | H40: DO NOT MIX!
...

Sheet 3'_OCM_4plex
C1: Checklist 10X 3’ Gene Expression v4 4-plex (OCM)
A2: Library prep number:
A3: SOP Version: | K3: Indexplate A: | L3: TT Set A
A4: GEM kit LOT#: | J4: Signature:
A5: Gel Bead kit LOT#:
A6: OCM 3' Chip Kit LOT#
A7: Library prep kit C LOT#:
A8: Library person:
A9: Library date:
A10: Comments:
A11: Number of samples:
B12: GEM Generation & Barcoding
B13: Equilibrate beads to RT for 30 min
B14: Prepare the following MM and pipet 7.4 µL in each tube on ice
E15: Volume per 4-plex +10% | F15: =CONCATENATE(" Volume for ",$E$11," samples") -> Volume for samples
B16: Mix: | D16: RT Reagent E | E16: 17.18 | F16: =E16*$E$11*1.1 -> 0 | G16: µL
D17: Template Switch Oligo B | E17: 3.18 | F17: =E17*$E$11*1.1 -> 0 | G17: µL
D18: Reducing Agent B | E18: 2 | F18: =E18*$E$11*1.1 -> 0 | G18: µL
D19: RT Enzyme E | E19: 7.18 | F19: =E19*$E$11*1.1 -> 0 | G19: µL
E20: =SUM(E16:E19) -> 29.54 | F20: =SUM(F16:F19) -> 0 | G20: µL | H20: mix, spin
B21: Assemble the Cip and pipet glycerol in the unused wells: 15 µL into ROW 1, 18 µL into ROW 2, 70 µL into ROW 3
B22: Add 1x PBS into the MM for each sample and mix
D23: Sample name | E23: cell count/mL | F23: V H2O [µL] | G23: V Sample [µL] | J23: normally we target cell number 16500
C24: 1 | D24: ='10X_table'!C2 -> 0
C25: 2 | D25: ='10X_table'!C3 -> 0
C26: 3 | D26: ='10X_table'!C4 -> 0
C27: 4 | D27: ='10X_table'!C5 -> 0
C28: 5 | D28: ='10X_table'!C6 -> 0
C29: 6 | D29: ='10X_table'!C7 -> 0
C30: 7 | D30: ='10X_table'!C8 -> 0
C31: 8 | D31: ='10X_table'!C9 -> 0
B32: Using a multichannel pipet 15 µl of the Master Mix + Cell suspension into the chip in row 1
B33: Vortex beads for 30 sec, centrifuge, with a multichannel pipet 18 µl into row 2 and wait for 30s.
B34: Using a mltichannel pipet 70 µl of partitioning oil B in row 3
B35: Close lid and put it into chromium
B36: Transfer gems into tubes with cap put it into thermocycler and Incubate: | I36: 48°C/45 min | K36: lid = 48°C, volume 125 µL
I37: 85°C/5 min -> hold 4°C
B38: Post GEM-RT Cleanup & cDNA Amplification
B39: Add 125 µL of Recovery Agent to each sample, wait for 2 min | H39: DO NOT MIX!
B40: Remove the recovery agent/oil (pink) | H40: DO NOT ASPIRTE aqueous sample
...

Sheet Flex_GEMX_v2
C1: Checklist 10X Fixed RNA GEMX v2 plate based with pooled wash workflow
A2: Library prep number: | J2: Indexplate GEX: | K2: TS Set A
A3: SOP Version: | I3: Signature: | L3: Indexplate
A4: GEM-X Flex GEM & Library Kit v2 LOT#: | I4: Organism:
A5: GEM-X Flex Hybridization and Wash kit v2 LOT#: | J5: Barcode Oligo plate:
A6: GEM-X Flex Human/Mouse Transcirptome Probe kit v2 LOT#: | I6: GEM-X Flex Barcode Oligo Plate v2 LOT#:
A7: GEX-X Flex Gel Bead Kit v2 LOT#:
A8: Chip Kit LOT#
A9: Dual Index Kit TS Set A LOT#
A10: Library person: | I10: for low input samples please adjust the checklist to the user guide
A11: Library date:
A12: Comments:
A13: Number of samples: | E13: 4 | F13: 1 | G13: Number of GEM reactions: | J13: 1
B14: Post Storage Processing
B15: Thaw samples at RT not ICE!
B16: Prepare Quenching Buffer B on ice and mix.
D17: Reagent | E17: 1x [µL] | F17: =CONCATENATE(" Volume for ",$E$13," samples +20%") -> Volume for 4 samples +20%
D18: Nuclease free water | E18: =500-62.5 -> 437.5 | F18: =E18*E13*1.2 -> 2100
D19: Conc. Quenching Buffer B | E19: =62.5 -> 62.5 | F19: =E19*E13*1.2 -> 300
B20: Centrifuge sample at 850 rcf for 5 minutes at room temperature.
B21: Remove supernatant and resuspend in 0.5 mL of the prepared solution. Keep on ice. | K21: cool centrifuge to 4°C
B22: Determine cell count (when counting with AO/PI dilute 1:5 first).
D23: Sample ID | E23: Cell concentration [cells/µL] | H23: Sample ID | I23: Cell concentration [cells/µL]
D24: {=[1]FLEX_table!B2:B9} -> 0 | H24: {=[1]FLEX_table!B10:B17} -> 0
D25: 0 | H25: 0
D26: 0 | H26: 0
D27: 0 | H27: 0
D28: 0 | H28: 0
D29: 0 | H29: 0
D30: 0 | H30: 0
D31: 0 | H31: 0
B32: Probe Hybridization
B33: Thaw Hyb Buffer B at 42°C, keep warm (can be kept a 42°C for up to an hour).
B34: Thaw Enhancer 10 min at 65°C, can be held at 42°C for 10 min.
B35: Thaw Probes on ice, vortex and centrifuge.
B36: Thaw Addtitive A at RT vortex and centrifuge, maintain on ice.
B37: Prepare the following Hyb mix at RT and incubate for 5 min at 42°C.
E38: Volume per reaction | F38: =CONCATENATE(" Volume for ",$E$13," samples +10%") -> Volume for 4 samples +10% | J38: Sample Type | L38: Recommended multiplex | N38: Recommended singleplex
D39: Hyb Buffer B | E39: 35 | F39: =E39*$E$13*1.1 -> 154 | G39: µL | J39: Fixed cells | L39: 50 000- 500 000 | N39: 300 000
D40: Enhancer | E40: 5 | F40: =E40*$E$13*1.1 -> 22 | G40: µL | S40: sample NR | T40: volume used for hybiridzation [µL]
...

Sheet 5'_GEMX
C1: Checklist 10X 5’ Cell MULTIPLEXING and AB capture
A2: Library prep number: | K2: Indexplate GEX: | L2: TT Set A
A3: SOP Version: | J3: Signature: | M3: Indexplate | O3: THIS IS DIFFERENT FROM ANTIBODY CAPTURE TOTALSEQ A
A4: GEM Bead Kit LOT#: | K4: TotalseqC | L4: Yes | M4: TN Set A
A5: GEM generation Kit LOT#: | K5: AB capture | L5: Yes | M5: TN Set A
A6: Chip G Kit LOT# | K6: VDJ | L6: Yes | M6: TT Set A
A7: Library prep Kit LOT#:
A8: Dual Index Kit TT Set A LOT#
A9: Library person:
A10: Library date:
A11: Comments:
A12: Number of samples:
B13: GEM Generation & Barcoding
B14: Equilibrate beads and reagents to RT for 30 min
B15: Prepare the following MM and pipet 31.9 µL in each tube on ice
E16: Volume per reaction | F16: =CONCATENATE(" Volume for ",$E$12," samples") -> Volume for samples
B17: Mix: | D17: RT Reagent E | E17: 16.3 | F17: =E17*$E$12*1.1 -> 0 | G17: µL
D18: Poly-dt RT Primer B | E18: 2.2 | F18: =E18*$E$12*1.1 -> 0 | G18: µL
D19: Reducing Agent B | E19: 2 | F19: =E19*$E$12*1.1 -> 0 | G19: µL
D20: RT Enzyme E | E20: 7 | F20: =E20*$E$12*1.1 -> 0 | G20: µL
E21: =SUM(E17:E20) -> 27.5 | F21: =SUM(F17:F20) -> 0 | G21: µL | H21: mix, spin
B22: Assemble the Chip X and pipet glycerol in the unused wells: 60 µL into ROW 1, 60 µL into ROW 2, 125 µL x 2 into ROW 3
B23: Calculate the needed dilutions of the sample with the following formula
C24: Sample name | E24: PBS [µL] | F24: Sample [µL] | I24: normally we targetd cell number 29000
B33: Pipet 60 µl of the Master Mix + Cell suspension into the chip in row 1
B34: Vortex beads for 30 sec, centrifuge, pipet 60 µl into row 2 and wait for 30s.
B35: Pipet 2x 125 µl of partitioning oil in row 3
B36: Close lid and put it into chromium
B37: Transfer gems into tubes with cap put it into thermocycler and Incubate: | J37: 48°C/45 min | L37: lid = 48°C, volume 125 µL
J38: 85°C/5 min -> hold 4°C
B39: Post GEM-RT Cleanup & cDNA Amplification
B40: Add 125 µL of Recovery Agent to each sample, wait for 2 min | J40: DO NOT MIX!
B41: Remove the 125 µL recovery agent/oil (pink) | H41: DO NOT ASPIRTE aqueous sample
B42: Add 200 µL of Dynabeads cleanup mix to each sample, incubate 10 min and mix after 5 min | G42: Dynabeads Mix: | J42: Volume per reaction | K42: =CONCATENATE(" Volume for ",$E$12," samples") -> Volume for samples
G43: Cleanup buffer | J43: 182 | K43: =J43*$E$12*1.1 -> 0 | L43: µL
C44: Thaw the Cleanup buffer at 65°C for 10 min, cool to RT | G44: Dynabeads | J44: 8 | K44: =J44*$E$12*1.1 -> 0 | L44: µL
G45: Reducing Agent B | J45: 5 | K45: =J45*$E$12*1.1 -> 0 | L45: µL
G46: Nuclease free water | J46: 5 | K46: =J46*$E$12*1.1 -> 0 | L46: µL
J47: =SUM(J43:J46) -> 200 | K47: =SUM(K43:K46) -> 0 | L47: µL | M47: mix, spin
B48: Prepare ES 1: | E48: Volume per reaction | F48: =CONCATENATE(" Volume for ",$E$12," samples") -> Volume for samples
...

Sheet 5'_OCM_4plex
C1: Checklist 10X 5’ Gene Expression v4 4-plex (OCM)
A2: Library prep number:
A3: SOP Version: | K3: Indexplate A: | L3: TT Set A
A4: GEM kit LOT#: | J4: Signature:
A5: Gel Bead kit LOT#:
A6: OCM 5' Chip Kit LOT#
A7: Library prep kit C LOT#:
A8: Library person:
A9: Library date:
A10: Comments:
A11: Number of samples:
B12: GEM Generation & Barcoding
B13: Equilibrate beads to RT for 30 min
B14: Prepare the following MM and pipet 7.4 µL in each tube on ice
E15: Volume per 4-plex +10% | F15: =CONCATENATE(" Volume for ",$E$11," samples") -> Volume for samples
B16: Mix: | C16: RT Reagent E | E16: 18.9 | F16: =E16*$E$11*1.1 -> 0 | G16: µL
C17: Poly-dt RT Primer B | E17: 2.6 | F17: =E17*$E$11*1.1 -> 0 | G17: µL
C18: Reducing Agent B | E18: 2.2 | F18: =E18*$E$11*1.1 -> 0 | G18: µL
C19: RT Enzyme E | E19: 7.9 | F19: =E19*$E$11*1.1 -> 0 | G19: µL
E20: =SUM(E16:E19) -> 31.6 | F20: =SUM(F16:F19) -> 0 | G20: µL | H20: mix, spin
B21: Assemble the Cip and pipet glycerol in the unused wells: 15 µL into ROW 1, 18 µL into ROW 2, 70 µL into ROW 3
B22: Add appropriate volume (total 17µL) of 1x PBS into the MM for each sample and mix
D23: Sample name | E23: cell count/mL | F23: V H2O [µL] | G23: V Sample [µL] | J23: normally we target cell number 8250 to load
C24: 1 | D24: ='10X_table'!B2 -> 0
C25: 2 | D25: ='10X_table'!B3 -> 0
C26: 3 | D26: ='10X_table'!B4 -> 0
C27: 4 | D27: ='10X_table'!B5 -> 0
C28: 5 | D28: ='10X_table'!B6 -> 0
C29: 6 | D29: ='10X_table'!B7 -> 0
C30: 7 | D30: ='10X_table'!B8 -> 0
C31: 8 | D31: ='10X_table'!B9 -> 0
B32: Using a multichannel pipet 15 µl of the Master Mix + Cell suspension into the chip in row 1
B33: Vortex beads for 30 sec, centrifuge, with a multichannel pipet 18 µl into row 2 and wait for 30s.
B34: Using a mltichannel pipet 70 µl of partitioning oil B in row 3
B35: Close lid and put it into chromium
B36: Transfer gems into tubes with cap put it into thermocycler and Incubate: | I36: 48°C/45 min | K36: lid = 48°C, volume 125 µL
I37: 85°C/5 min -> hold 4°C
B38: Post GEM-RT Cleanup & cDNA Amplification
B39: Add 125 µL of Recovery Agent to each sample, wait for 2 min | J39: DO NOT MIX!
B40: Remove the recovery agent/oil (pink) | J40: DO NOT ASPIRTE aqueous sample
...

Sheet Equal_Pooling_RevB
B1: Chromium Fixed RNA Profiling for Multiplexed Samples - Pooling Workbook | 10xgenomics.com CG000565 Rev B
B2: Equal Pooling (Recommended)
B4: Equal pooling refers to pooling the same number of cells from each probe-hybridized sample. It is the recommended method for pooling and ensures that the undetected multiplet rates are the same for each Probe Barcode. Pooling the same number of cells should also result in an approximately equal numbers of cells recovered from every Probe Barcode in the final library. See below for worksheet to calculate the sample volumes to be added during pooling.
B6: Numbers filled In this tab will auto-populate other tabs
B7: This calculator is meant to facilitate pooling an equal number of cells from different hybridization reactions prior to washing.
B9: 1. | C9: Enter Post-Hybridization Cell Concentration and Sample Volume (volume remaining after counting) in columns C and D (blue columns) in Table 1.
B10: 2. | C10: Use the volumes indicated in the column H (green column) to pool the samples from different hybridization reactions into a 5-ml (for 4 pooling samples) or 15-ml (for pooling 16 samples) centrifuge tube. If the differences in 'Total Cells in Hybridization' between samples are smaller than the expected error from cell counting, the entire volume from each sample can be added to the pool. If a warning message appears next to Table 2, consider alternative pooling strategies.
B11: 3. | C11: If hybridization was performed in 8-tube strips, add 2.3 ml Post-Hyb Wash Buffer (if pooling 4 samples) or 9.2 ml Post-Hyb Wash Buffer (if pooling 16 samples). Mix by inverting 5x.
B13: Table 1
B14: Probe Barcode | C14: Post-Hybridization Cell Concentration (Cells in Post-Hyb Wash Buffer) | D14: Post-Hybridization Sample Volume | E14: Total Cells in Hybridization (Post-Hyb Cell Conc. * Volume) | F14: % of Final Pool | G14: Cells per Sample Added to the Pool (Cell Count of Sample with Lowest Concentration) | H14: Sample Volume to be Added (Cells per Sample Added to the Pool/ Post-Hybridization Cell Conc.) | I14: Expected Cells Recovered per Probe Barcode (Assumes Maximum Supported Number of Cells Targeted per GEM Reaction) | J14: Max. Expected Cells recovered per barcode Given Limiting cell number
B15: BC001 | C15: =FLEX_table!$H2 -> 0 | E15: =IF(ISBLANK(Table_2[[#This Row],[Post-Hybridization Sample Volume ]]),"", IF((C15*D15)>0,C15*D15,)) | F15: =IF(ISBLANK(Table_2[[#This Row],[Post-Hybridization Sample Volume ]]),"",1/(COUNT($E$15:$E$30))) | G15: =IF(ISBLANK(Table_2[[#This Row],[Post-Hybridization Sample Volume ]]),"",MIN($E$15:$E$30)) | H15: =IF(ISBLANK(Table_2[[#This Row],[Post-Hybridization Sample Volume ]]),"",G15/C15) | I15: =IF(ISBLANK(Table_2[[#This Row],[Post-Hybridization Sample Volume ]]),"",(IF($B$34>4,F15/MAX($F$15:$F$30)*8000,F15/MAX($F$15:$F$30)*10000))) | J15: =IF(ISBLANK(Table_2[[#This Row],[Post-Hybridization Sample Volume ]]),"", IF(G15>I15*1.65/0.8,I15, ($C$34/SUM($I$15:$I$30)*I15)*0.8/1.65))
B16: BC002 | C16: =FLEX_table!$H3 -> 0 | E16: =IF(ISBLANK(Table_2[[#This Row],[Post-Hybridization Sample Volume ]]),"", IF((C16*D16)>0,C16*D16,)) | F16: =IF(ISBLANK(Table_2[[#This Row],[Post-Hybridization Sample Volume ]]),"",1/(COUNT($E$15:$E$30))) | G16: =IF(ISBLANK(Table_2[[#This Row],[Post-Hybridization Sample Volume ]]),"",MIN($E$15:$E$30)) | H16: =IF(ISBLANK(Table_2[[#This Row],[Post-Hybridization Sample Volume ]]),"",G16/C16) | I16: =IF(ISBLANK(Table_2[[#This Row],[Post-Hybridization Sample Volume ]]),"",(IF($B$34>4,F16/MAX($F$15:$F$30)*8000,F16/MAX($F$15:$F$30)*10000))) | J16: =IF(ISBLANK(Table_2[[#This Row],[Post-Hybridization Sample Volume ]]),"", IF(G16>I16*1.65/0.8,I16, ($C$34/SUM($I$15:$I$30)*I16)*0.8/1.65))
B17: BC003 | C17: =FLEX_table!$H4 -> 0 | E17: =IF(ISBLANK(Table_2[[#This Row],[Post-Hybridization Sample Volume ]]),"", IF((C17*D17)>0,C17*D17,)) | F17: =IF(ISBLANK(Table_2[[#This Row],[Post-Hybridization Sample Volume ]]),"",1/(COUNT($E$15:$E$30))) | G17: =IF(ISBLANK(Table_2[[#This Row],[Post-Hybridization Sample Volume ]]),"",MIN($E$15:$E$30)) | H17: =IF(ISBLANK(Table_2[[#This Row],[Post-Hybridization Sample Volume ]]),"",G17/C17) | I17: =IF(ISBLANK(Table_2[[#This Row],[Post-Hybridization Sample Volume ]]),"",(IF($B$34>4,F17/MAX($F$15:$F$30)*8000,F17/MAX($F$15:$F$30)*10000))) | J17: =IF(ISBLANK(Table_2[[#This Row],[Post-Hybridization Sample Volume ]]),"", IF(G17>I17*1.65/0.8,I17, ($C$34/SUM($I$15:$I$30)*I17)*0.8/1.65))
B18: BC004 | C18: =FLEX_table!$H5 -> 0 | E18: =IF(ISBLANK(Table_2[[#This Row],[Post-Hybridization Sample Volume ]]),"", IF((C18*D18)>0,C18*D18,)) | F18: =IF(ISBLANK(Table_2[[#This Row],[Post-Hybridization Sample Volume ]]),"",1/(COUNT($E$15:$E$30))) | G18: =IF(ISBLANK(Table_2[[#This Row],[Post-Hybridization Sample Volume ]]),"",MIN($E$15:$E$30)) | H18: =IF(ISBLANK(Table_2[[#This Row],[Post-Hybridization Sample Volume ]]),"",G18/C18) | I18: =IF(ISBLANK(Table_2[[#This Row],[Post-Hybridization Sample Volume ]]),"",(IF($B$34>4,F18/MAX($F$15:$F$30)*8000,F18/MAX($F$15:$F$30)*10000))) | J18: =IF(ISBLANK(Table_2[[#This Row],[Post-Hybridization Sample Volume ]]),"", IF(G18>I18*1.65/0.8,I18, ($C$34/SUM($I$15:$I$30)*I18)*0.8/1.65))
B19: BC005 | C19: =FLEX_table!$H6 -> 0 | E19: =IF(ISBLANK(Table_2[[#This Row],[Post-Hybridization Sample Volume ]]),"", IF((C19*D19)>0,C19*D19,)) | F19: =IF(ISBLANK(Table_2[[#This Row],[Post-Hybridization Sample Volume ]]),"",1/(COUNT($E$15:$E$30))) | G19: =IF(ISBLANK(Table_2[[#This Row],[Post-Hybridization Sample Volume ]]),"",MIN($E$15:$E$30)) | H19: =IF(ISBLANK(Table_2[[#This Row],[Post-Hybridization Sample Volume ]]),"",G19/C19) | I19: =IF(ISBLANK(Table_2[[#This Row],[Post-Hybridization Sample Volume ]]),"",(IF($B$34>4,F19/MAX($F$15:$F$30)*8000,F19/MAX($F$15:$F$30)*10000))) | J19: =IF(ISBLANK(Table_2[[#This Row],[Post-Hybridization Sample Volume ]]),"", IF(G19>I19*1.65/0.8,I19, ($C$34/SUM($I$15:$I$30)*I19)*0.8/1.65))
B20: BC006 | C20: =FLEX_table!$H7 -> 0 | E20: =IF(ISBLANK(Table_2[[#This Row],[Post-Hybridization Sample Volume ]]),"", IF((C20*D20)>0,C20*D20,)) | F20: =IF(ISBLANK(Table_2[[#This Row],[Post-Hybridization Sample Volume ]]),"",1/(COUNT($E$15:$E$30))) | G20: =IF(ISBLANK(Table_2[[#This Row],[Post-Hybridization Sample Volume ]]),"",MIN($E$15:$E$30)) | H20: =IF(ISBLANK(Table_2[[#This Row],[Post-Hybridization Sample Volume ]]),"",G20/C20) | I20: =IF(ISBLANK(Table_2[[#This Row],[Post-Hybridization Sample Volume ]]),"",(IF($B$34>4,F20/MAX($F$15:$F$30)*8000,F20/MAX($F$15:$F$30)*10000))) | J20: =IF(ISBLANK(Table_2[[#This Row],[Post-Hybridization Sample Volume ]]),"", IF(G20>I20*1.65/0.8,I20, ($C$34/SUM($I$15:$I$30)*I20)*0.8/1.65))
B21: BC007 | C21: =FLEX_table!$H8 -> 0 | E21: =IF(ISBLANK(Table_2[[#This Row],[Post-Hybridization Sample Volume ]]),"", IF((C21*D21)>0,C21*D21,)) | F21: =IF(ISBLANK(Table_2[[#This Row],[Post-Hybridization Sample Volume ]]),"",1/(COUNT($E$15:$E$30))) | G21: =IF(ISBLANK(Table_2[[#This Row],[Post-Hybridization Sample Volume ]]),"",MIN($E$15:$E$30)) | H21: =IF(ISBLANK(Table_2[[#This Row],[Post-Hybridization Sample Volume ]]),"",G21/C21) | I21: =IF(ISBLANK(Table_2[[#This Row],[Post-Hybridization Sample Volume ]]),"",(IF($B$34>4,F21/MAX($F$15:$F$30)*8000,F21/MAX($F$15:$F$30)*10000))) | J21: =IF(ISBLANK(Table_2[[#This Row],[Post-Hybridization Sample Volume ]]),"", IF(G21>I21*1.65/0.8,I21, ($C$34/SUM($I$15:$I$30)*I21)*0.8/1.65))
B22: BC008 | C22: =FLEX_table!$H9 -> 0 | E22: =IF(ISBLANK(Table_2[[#This Row],[Post-Hybridization Sample Volume ]]),"", IF((C22*D22)>0,C22*D22,)) | F22: =IF(ISBLANK(Table_2[[#This Row],[Post-Hybridization Sample Volume ]]),"",1/(COUNT($E$15:$E$30))) | G22: =IF(ISBLANK(Table_2[[#This Row],[Post-Hybridization Sample Volume ]]),"",MIN($E$15:$E$30)) | H22: =IF(ISBLANK(Table_2[[#This Row],[Post-Hybridization Sample Volume ]]),"",G22/C22) | I22: =IF(ISBLANK(Table_2[[#This Row],[Post-Hybridization Sample Volume ]]),"",(IF($B$34>4,F22/MAX($F$15:$F$30)*8000,F22/MAX($F$15:$F$30)*10000))) | J22: =IF(ISBLANK(Table_2[[#This Row],[Post-Hybridization Sample Volume ]]),"", IF(G22>I22*1.65/0.8,I22, ($C$34/SUM($I$15:$I$30)*I22)*0.8/1.65))
B23: BC009 | C23: =FLEX_table!$H10 -> 0 | E23: =IF(ISBLANK(Table_2[[#This Row],[Post-Hybridization Sample Volume ]]),"", IF((C23*D23)>0,C23*D23,)) | F23: =IF(ISBLANK(Table_2[[#This Row],[Post-Hybridization Sample Volume ]]),"",1/(COUNT($E$15:$E$30))) | G23: =IF(ISBLANK(Table_2[[#This Row],[Post-Hybridization Sample Volume ]]),"",MIN($E$15:$E$30)) | H23: =IF(ISBLANK(Table_2[[#This Row],[Post-Hybridization Sample Volume ]]),"",G23/C23) | I23: =IF(ISBLANK(Table_2[[#This Row],[Post-Hybridization Sample Volume ]]),"",(IF($B$34>4,F23/MAX($F$15:$F$30)*8000,F23/MAX($F$15:$F$30)*10000))) | J23: =IF(ISBLANK(Table_2[[#This Row],[Post-Hybridization Sample Volume ]]),"", IF(G23>I23*1.65/0.8,I23, ($C$34/SUM($I$15:$I$30)*I23)*0.8/1.65))
B24: BC010 | C24: =FLEX_table!$H11 -> 0 | E24: =IF(ISBLANK(Table_2[[#This Row],[Post-Hybridization Sample Volume ]]),"", IF((C24*D24)>0,C24*D24,)) | F24: =IF(ISBLANK(Table_2[[#This Row],[Post-Hybridization Sample Volume ]]),"",1/(COUNT($E$15:$E$30))) | G24: =IF(ISBLANK(Table_2[[#This Row],[Post-Hybridization Sample Volume ]]),"",MIN($E$15:$E$30)) | H24: =IF(ISBLANK(Table_2[[#This Row],[Post-Hybridization Sample Volume ]]),"",G24/C24) | I24: =IF(ISBLANK(Table_2[[#This Row],[Post-Hybridization Sample Volume ]]),"",(IF($B$34>4,F24/MAX($F$15:$F$30)*8000,F24/MAX($F$15:$F$30)*10000))) | J24: =IF(ISBLANK(Table_2[[#This Row],[Post-Hybridization Sample Volume ]]),"", IF(G24>I24*1.65/0.8,I24, ($C$34/SUM($I$15:$I$30)*I24)*0.8/1.65))
B25: BC011 | C25: =FLEX_table!$H12 -> 0 | E25: =IF(ISBLANK(Table_2[[#This Row],[Post-Hybridization Sample Volume ]]),"", IF((C25*D25)>0,C25*D25,)) | F25: =IF(ISBLANK(Table_2[[#This Row],[Post-Hybridization Sample Volume ]]),"",1/(COUNT($E$15:$E$30))) | G25: =IF(ISBLANK(Table_2[[#This Row],[Post-Hybridization Sample Volume ]]),"",MIN($E$15:$E$30)) | H25: =IF(ISBLANK(Table_2[[#This Row],[Post-Hybridization Sample Volume ]]),"",G25/C25) | I25: =IF(ISBLANK(Table_2[[#This Row],[Post-Hybridization Sample Volume ]]),"",(IF($B$34>4,F25/MAX($F$15:$F$30)*8000,F25/MAX($F$15:$F$30)*10000))) | J25: =IF(ISBLANK(Table_2[[#This Row],[Post-Hybridization Sample Volume ]]),"", IF(G25>I25*1.65/0.8,I25, ($C$34/SUM($I$15:$I$30)*I25)*0.8/1.65))
B26: BC012 | C26: =FLEX_table!$H13 -> 0 | E26: =IF(ISBLANK(Table_2[[#This Row],[Post-Hybridization Sample Volume ]]),"", IF((C26*D26)>0,C26*D26,)) | F26: =IF(ISBLANK(Table_2[[#This Row],[Post-Hybridization Sample Volume ]]),"",1/(COUNT($E$15:$E$30))) | G26: =IF(ISBLANK(Table_2[[#This Row],[Post-Hybridization Sample Volume ]]),"",MIN($E$15:$E$30)) | H26: =IF(ISBLANK(Table_2[[#This Row],[Post-Hybridization Sample Volume ]]),"",G26/C26) | I26: =IF(ISBLANK(Table_2[[#This Row],[Post-Hybridization Sample Volume ]]),"",(IF($B$34>4,F26/MAX($F$15:$F$30)*8000,F26/MAX($F$15:$F$30)*10000))) | J26: =IF(ISBLANK(Table_2[[#This Row],[Post-Hybridization Sample Volume ]]),"", IF(G26>I26*1.65/0.8,I26, ($C$34/SUM($I$15:$I$30)*I26)*0.8/1.65))
... B30: BC016 | C30: =FLEX_table!$H17 -> 0 | E30: =IF(ISBLANK(Table_2[[#This Row],[Post-Hybridization Sample Volume ]]),"", IF((C30*D30)>0,C30*D30,)) | F30: =IF(ISBLANK(Table_2[[#This Row],[Post-Hybridization Sample Volume ]]),"",1/(COUNT($E$15:$E$30))) | G30: =IF(ISBLANK(Table_2[[#This Row],[Post-Hybridization Sample Volume ]]),"",MIN($E$15:$E$30)) | H30: =IF(ISBLANK(Table_2[[#This Row],[Post-Hybridization Sample Volume ]]),"",G30/C30) | I30: =IF(ISBLANK(Table_2[[#This Row],[Post-Hybridization Sample Volume ]]),"",(IF($B$34>4,F30/MAX($F$15:$F$30)*8000,F30/MAX($F$15:$F$30)*10000))) | J30: =IF(ISBLANK(Table_2[[#This Row],[Post-Hybridization Sample Volume ]]),"", IF(G30>I30*1.65/0.8,I30, ($C$34/SUM($I$15:$I$30)*I30)*0.8/1.65))
B32: Table 2
B33: Number of Probe Barcodes used | C33: Total Cells Pooled | D33: Maximum Number of Cells Targeted per GEM Reaction | E33: =IF(COUNTIF(D38:D52,"TRUE")>=1,"WARNING:"&CHAR(10)&_xlfn.TEXTJOIN(CHAR(10),TRUE,E38:E52),"") -> WARNING: • Total Cells Pooled for wash is below the recommended minimum of 200,000 cells. Consider an alternative pooling strategy.
B34: =COUNTIF(E15:E30,">0") -> 0 | C34: =SUM(G15:G30) -> 0 | D34: =IF(C34>SUM(I15:I30)*1.65/0.8,SUM(I15:I30), SUM(J15:J30)) -> 0
B37: Error | C37: Error Code | D37: Does Error Appear | E37: Cond. Error Message
B38: Bellow 200K Cells In Pool | C38: 1 | D38: =IF(C34<200000,TRUE,FALSE) -> TRUE | E38: =IF(D38,"• Total Cells Pooled for wash is below the recommended minimum of 200,000 cells. Consider an alternative pooling strategy.","") -> • Total Cells Pooled for wash is below the recommended minimum of 200,000 cells. Consider an alternative pooling strategy.
B39: Cells Pooled Cannot Reach Target GEM per BC | C39: 2 | D39: =IF(C34>=(SUM(I15:I30)*1.65/0.8), FALSE, TRUE) -> FALSE | E39: =IF(D39,"• Total number of cells added to wash is not sufficient to achieve the maximum supported number of cells targeted per GEM lane."&CHAR(10)& " The maximum possible cell number is displayed (assumes 20% cell loss during washes). If this cell number is insufficient for your experiment,"&CHAR(10)&" consider an alternative pooling strategy.","")
B40: Pipette Under 2ul | C40: 3 | D40: =IF(COUNTIF(H15:H30, "<2")>=1,TRUE,FALSE) -> FALSE | E40: =IF(D40,"• One or more samples have a low transfer volume that may result in higer cells-per-barcode variability. Verify cell concentrations"&CHAR(10)& " are entered correctly, then dilute with addtional post-hyb wash buffer and recount if necessary.","")
B41: Hyb Reaction has more than 5 million cells | C41: 4 | D41: =IF(COUNTIF(E15:E30, ">5000000")>=1,TRUE,FALSE) -> FALSE | E41: =IF(D41,"• Greater than 5 million cells present in one or more samples. Verify that cell concentrations and volumes are entered correctly.","")

Sheet Pooling
A1: Sample ID | B1: fragment size | C1: Qubit | E1: nM total | F1: sample vol | G1: EB + Tween 0,1% | H1: [QB after Dilution to 3nM] | I1: nM after Dilution | K1: Legend
D2: ng/ul | E2: =(C2/(660*B2))*1000000 -> #DIV/0! | G2: =(E2*F2/3)-F2 -> #DIV/0! | I2: =(H2/(660*B2))*1000000 -> #DIV/0! | K2: Don't touch
D3: ng/ul | E3: =(C3/(660*B3))*1000000 -> #DIV/0! | G3: =(E3*F3/3)-F3 -> #DIV/0! | I3: =(H3/(660*B3))*1000000 -> #DIV/0! | K3: To key in
D4: ng/ul | E4: =(C4/(660*B4))*1000000 -> #DIV/0! | G4: =(E4*F4/3)-F4 -> #DIV/0! | I4: =(H4/(660*B4))*1000000 -> #DIV/0!
D5: ng/ul | E5: =(C5/(660*B5))*1000000 -> #DIV/0! | G5: =(E5*F5/3)-F5 -> #DIV/0! | I5: =(H5/(660*B5))*1000000 -> #DIV/0!
D6: ng/ul | E6: =(C6/(660*B6))*1000000 -> #DIV/0! | G6: =(E6*F6/3)-F6 -> #DIV/0! | I6: =(H6/(660*B6))*1000000 -> #DIV/0!
D7: ng/ul | E7: =(C7/(660*B7))*1000000 -> #DIV/0! | G7: =(E7*F7/3)-F7 -> #DIV/0! | I7: =(H7/(660*B7))*1000000 -> #DIV/0!
D8: ng/ul | E8: =(C8/(660*B8))*1000000 -> #DIV/0! | G8: =(E8*F8/3)-F8 -> #DIV/0! | I8: =(H8/(660*B8))*1000000 -> #DIV/0!
D9: ng/ul | E9: =(C9/(660*B9))*1000000 -> #DIV/0! | G9: =(E9*F9/3)-F9 -> #DIV/0! | I9: =(H9/(660*B9))*1000000 -> #DIV/0!
D10: ng/ul | E10: =(C10/(660*B10))*1000000 -> #DIV/0! | G10: =(E10*F10/3)-F10 -> #DIV/0! | I10: =(H10/(660*B10))*1000000 -> #DIV/0!
D11: ng/ul | E11: =(C11/(660*B11))*1000000 -> #DIV/0! | G11: =(E11*F11/3)-F11 -> #DIV/0! | I11: =(H11/(660*B11))*1000000 -> #DIV/0!
A14: Actual Pooling
A15: Sample ID | B15: nM after Dilution | D15: representation | E15: pipet for 3nM | F15: lane | G15: SAMPLE | H15: pool | I15: EB | J15: Qubit
A16: =A2 -> 0 | B16: =E2 -> #DIV/0! | C16: nM | D16: =C29 -> #DIV/0! | E16: =3/B16*D16*50 -> #DIV/0! | G16: 1 | H16: =SUM(E16:E24) -> #DIV/0! | I16: =50-H16 -> #DIV/0!
A17: =A3 -> 0 | B17: =E3 -> #DIV/0! | C17: nM | D17: =C30 -> #DIV/0! | E17: =3/B17*D17*50 -> #DIV/0! | G17: 2
A18: =A4 -> 0 | B18: =E4 -> #DIV/0! | C18: nM | D18: =C31 -> #DIV/0! | E18: =3/B18*D18*50 -> #DIV/0! | G18: 3
A19: =A5 -> 0 | B19: =E5 -> #DIV/0! | C19: nM | D19: =C32 -> #DIV/0! | E19: =3/B19*D19*50 -> #DIV/0! | G19: 4
A20: =A6 -> 0 | B20: =E6 -> #DIV/0! | C20: nM | D20: =C33 -> #DIV/0! | E20: =3/B20*D20*50 -> #DIV/0! | G20: 5
A21: =A7 -> 0 | B21: =E7 -> #DIV/0! | C21: nM | D21: =C34 -> #DIV/0! | E21: =3/B21*D21*50 -> #DIV/0! | G21: 6
A22: =A10 -> 0 | B22: =E8 -> #DIV/0! | C22: nM | D22: =C35 -> #DIV/0! | E22: =3/B22*D22*50 -> #DIV/0! | G22: 7
A23: =A12 -> 0 | B23: =E9 -> #DIV/0! | C23: nM | D23: =C36 -> #DIV/0! | E23: =3/B23*D23*50 -> #DIV/0! | G23: 8
A24: =A13 -> 0 | B24: =E10 -> #DIV/0! | C24: nM | D24: =C37 -> #DIV/0! | E24: =3/B24*D24*50 -> #DIV/0! | G24: 9
D25: =SUM(D16:D20) -> #DIV/0!
A28: Sample ID | B28: M Reads | C28: %
A29: =A2 -> 0 | C29: =B29/B$38 -> #DIV/0!
A30: =A3 -> 0 | C30: =B30/B$38 -> #DIV/0!
A31: =A4 -> 0 | C31: =B31/B$38 -> #DIV/0!
A32: =A5 -> 0 | C32: =B32/B$38 -> #DIV/0!
A33: =A6 -> 0 | C33: =B33/B$38 -> #DIV/0!
A34: =A7 -> 0 | C34: =B34/B$38 -> #DIV/0!
A35: =A8 -> 0 | C35: =B35/B$38 -> #DIV/0!
A36: =A9 -> 0 | C36: =B36/B$38 -> #DIV/0!
A37: =A10 -> 0 | C37: =B37/B$38 -> #DIV/0!
A38: Total | B38: =SUM(B29:B37) -> 0 | C38: =SUM(C29:C37) -> #DIV/0!

Sheet Sheet1
A1: actual sequence of the Probe Barcode | B1: sequence after translation in Cell Ranger analysis | C1: Probe Barcode ID | D1: sample number
A2: ACGTACGGGA | B2: ACGTACGGGA | C2: A-A01 | D2: 1
A3: CTACTTTCGT | B3: CTACTTTCGT | C3: A-B01 | D3: 2
A4: ACAGATTGAG | B4: ACAGATTGAG | C4: A-C01 | D4: 3
A5: ACACTTGGAG | B5: ACACTTGGAG | C5: A-D01 | D5: 4
A6: TGCAGTTGGT | B6: TGCAGTTGGT | C6: A-E01 | D6: 5
A7: TGTCTGGCAG | B7: TGTCTGGCAG | C7: A-F01 | D7: 6
A8: TCCGTGCGTA | B8: TCCGTGCGTA | C8: A-G01 | D8: 7
A9: GAGGAGAACT | B9: GAGGAGAACT | C9: A-H01 | D9: 8
A10: GAATGGGAAG | B10: GAATGGGAAG | C10: A-A02 | D10: 9
A11: CACGAATCCA | B11: CACGAATCCA | C11: A-B02 | D11: 10
A12: GTGCCCGATA | B12: GTGCCCGATA | C12: A-C02 | D12: 11
A13: TGCCTCCATG | B13: TGCCTCCATG | C13: A-D02 | D13: 12
... A97: AGTCCCAGCT | B97: AGTCCCAGCT | C97: A-H12 | D97: 96
A98: AGGTCGGTCT | B98: AGGTCGGTCT | C98: B-A01
A99: CTCATACAAC | B99: CTCATACAAC | C99: B-A02
A100: AGGAAATCCA | B100: AGGAAATCCA | C100: B-A03
A101: CATGACGGTG | B101: CATGACGGTG | C101: B-A04
A102: TGGCGGTATG | B102: TGGCGGTATG | C102: B-A05
A103: CTATAGGGTA | B103: CTATAGGGTA | C103: B-A06
A104: GATAGAACAC | B104: GATAGAACAC | C104: B-A07
A105: ACTAAACGCT | B105: ACTAAACGCT | C105: B-A08
A106: CTATCTTGTG | B106: CTATCTTGTG | C106: B-A09
A107: GAGTGCCTGT | B107: GAGTGCCTGT | C107: B-A10
A108: ACCGTTATGT | B108: ACCGTTATGT | C108: B-A11
A109: TGGTTTAGCA | B109: TGGTTTAGCA | C109: B-A12
... A385: TCGCTTGGGA | B385: TCGCTTGGGA | C385: D-H12
